Workbook
Name _: Insed
Name _: Insed
Name _: Insed
Name _: Insed
Name _1: #REF!
Name _2: #REF!
Name _3: #REF!
Name _4: #REF!
Name _5: #REF!
Name _a: #REF!
Name A: #REF!
Name A: #REF!
Name A: #REF!
Name aa: #REF!
Name aaaa: #REF!
Name AB: [1]bener!$E$11
Name AB: [1]bener!$E$11
Name AB: [2]bener!$E$11
Name ass: #REF!
Name B: '[3]METODE HASPERS'!$B$1:$C$5
Name BanyakData: '[4]Statistik Dasar'!$D$35
Name BanyakData: '[4]Statistik Dasar'!$D$35
Name BanyakData: '[5]Statistik Dasar'!$D$19
Name baru: #REF!
Name baru: #REF!
Name baru: #REF!
Name C_: #REF!
Name CaraUrutData: '[6]Input Data'!#REF!
Name CaraUrutData: '[5]Input Data'!#REF!
Name CaraUrutData: '[5]Input Data'!#REF!
Name CaraUrutData: 'Input Data'!#REF!
Name ChiKritik: #REF!
Name ChiKritik: #REF!
Name ChiKritik: '[5]Uji Chi-Square'!$H$31
Name ChiKuadratGumbel: #REF!
Name ChiKuadratGumbel: #REF!
Name ChiKuadratGumbel: #REF!
Name ChiKuadratLogNorm: #REF!
Name ChiKuadratLogNorm: #REF!
Name ChiKuadratLogNorm: #REF!
Name ChiKuadratLogPearson: #REF!
Name ChiKuadratLogPearson: #REF!
Name ChiKuadratLogPearson: #REF!
Name ChiKuadratMinimum: #REF!
Name ChiKuadratMinimum: #REF!
Name ChiKuadratMinimum: '[5]Uji Chi-Square'!$H$29
Name CI: '[6]Input Data'!#REF!
Name CI: '[5]Input Data'!#REF!
Name CI: '[5]Input Data'!#REF!
Name CI: '[4]Input Data'!$B$5
Name CI: '[4]Input Data'!$B$5
Name CI: 'Input Data'!#REF!
Name CsX: [7]statis!$D$19
Name CsX: [7]statis!$D$19
Name CsX: [8]statis!$D$19
Name D: #REF!
Name Data: 'Input Data'!$B$2:$C$13
Name Dd: #REF!
Name Delta: #REF!
Name Delta: #REF!

Sheet Rainfall Data
A1: Pontianak Kota Climatology Station | D1: West Kalimantan Climatology Station | G1: Pontianak Maritime Meteorology Station
A2: Year | B2: R MAX | D2: Year | E2: R MAX | G2: Year | H2: R MAX
A3: 2013 | B3: 112 | D3: 2013 | E3: 84 | G3: 2013 | H3: 120
A4: 2014 | B4: 155 | D4: 2014 | E4: 109 | G4: 2014 | H4: 150
A5: 2015 | B5: 79 | D5: 2015 | E5: 66 | G5: 2015 | H5: 87
A6: 2016 | B6: 85 | D6: 2016 | E6: 70 | G6: 2016 | H6: 87
A7: 2017 | B7: 165 | D7: 2017 | E7: 111 | G7: 2017 | H7: 102
A8: 2018 | B8: 115 | D8: 2018 | E8: 116 | G8: 2018 | H8: 119
A9: 2019 | B9: 112 | D9: 2019 | E9: 121 | G9: 2019 | H9: 136
A10: 2020 | B10: 154 | D10: 2020 | E10: 164 | G10: 2020 | H10: 168
A11: 2021 | B11: 200 | D11: 2021 | E11: 194 | G11: 2021 | H11: 154
A12: 2022 | B12: 112 | D12: 2022 | E12: 106 | G12: 2022 | H12: 119
A13: 2023 | B13: 89 | D13: 2023 | E13: 107 | G13: 2023 | H13: 103
A14: 2024 | B14: 129 | D14: 2024 | E14: 130 | G14: 2024 | H14: 154

Sheet Thiessen Polygon Influence Zone
B3: No | C3: STA Name | D3: Thiessen polygon influence zones (Km)
B4: 1 | C4: Pontianak Kota Climatology Station | D4: 54.488492
B5: 2 | C5: West Kalimantan Climatology Station | D5: 2.178292
B6: 3 | C6: Pontianak Maritime Meteorology Station | D6: 229.57738
B8: Total Luas Area | D8: =SUM(D4:D7) -> 286.24417

Sheet Thiessen
F3: ='Thiessen Polygon Influence Zone'!C4 -> Pontianak Kota Climatology Station | G3: ='Thiessen Polygon Influence Zone'!D4 -> 54.488492 | I3: ='Thiessen Polygon Influence Zone'!C5 -> West Kalimantan Climatology Station | J3: ='Thiessen Polygon Influence Zone'!D5 -> 2.178292 | L3: ='Thiessen Polygon Influence Zone'!C6 -> Pontianak Maritime Meteorology Station | M3: ='Thiessen Polygon Influence Zone'!D6 -> 229.57738
F4: TAHUN | G4: R MAX | I4: TAHUN | J4: R MAX | L4: TAHUN | M4: R MAX
F5: 2013 | G5: 112 | I5: 2013 | J5: 84 | L5: 2013 | M5: 120
F6: 2014 | G6: 155 | I6: 2014 | J6: 109 | L6: 2014 | M6: 150
F7: 2015 | G7: 79 | I7: 2015 | J7: 66 | L7: 2015 | M7: 87
F8: 2016 | G8: 85 | I8: 2016 | J8: 70 | L8: 2016 | M8: 87
F9: 2017 | G9: 165 | I9: 2017 | J9: 111 | L9: 2017 | M9: 102
F10: 2018 | G10: 115 | I10: 2018 | J10: 116 | L10: 2018 | M10: 119
F11: 2019 | G11: 112 | I11: 2019 | J11: 121 | L11: 2019 | M11: 136
F12: 2020 | G12: 154 | I12: 2020 | J12: 164 | L12: 2020 | M12: 168
F13: 2021 | G13: 200 | I13: 2021 | J13: 194 | L13: 2021 | M13: 154
F14: 2022 | G14: 112 | I14: 2022 | J14: 106 | L14: 2022 | M14: 119
F15: 2023 | G15: 89 | I15: 2023 | J15: 107 | L15: 2023 | M15: 103
F16: 2024 | G16: 129 | I16: 2024 | J16: 130 | L16: 2024 | M16: 154
N20: No. | O20: Year | P20: Rainfall (mm)
C21: Thiessen | P21: Pontianak Kota Climatology Station | Q21: West Kalimantan Climatology Station | R21: Pontianak Maritime Meteorology Station | S21: Thiessen (mm)
P22: Polygon area (Km2)
C23: TAHUN | D23: R MAX | P23: =G3 -> 54.488492 | Q23: =J3 -> 2.178292 | R23: =M3 -> 229.57738
C24: 2013 | D24: =((G5*$G$3)+(J5*$J$3)+(M5*$M$3))/'Thiessen Polygon Influence Zone'!$D$8 -> 118.20319 | N24: 1 | O24: 2013 | P24: 112 | Q24: 84 | R24: 120 | S24: 118.20319
C25: 2014 | D25: =((G6*$G$3)+(J6*$J$3)+(M6*$M$3))/'Thiessen Polygon Influence Zone'!$D$8 -> 150.63978 | N25: 2 | O25: 2014 | P25: 155 | Q25: 109 | R25: 150 | S25: 150.63978
C26: 2015 | D26: =((G7*$G$3)+(J7*$J$3)+(M7*$M$3))/'Thiessen Polygon Influence Zone'!$D$8 -> 85.317338 | N26: 3 | O26: 2015 | P26: 79 | Q26: 66 | R26: 87 | S26: 85.317338
C27: 2016 | D27: =((G8*$G$3)+(J8*$J$3)+(M8*$M$3))/'Thiessen Polygon Influence Zone'!$D$8 -> 86.489918 | N27: 4 | O27: 2016 | P27: 85 | Q27: 70 | R27: 87 | S27: 86.489918
C28: 2017 | D28: =((G9*$G$3)+(J9*$J$3)+(M9*$M$3))/'Thiessen Polygon Influence Zone'!$D$8 -> 114.06096 | N28: 5 | O28: 2017 | P28: 165 | Q28: 111 | R28: 102 | S28: 114.06096
C29: 2018 | D29: =((G10*$G$3)+(J10*$J$3)+(M10*$M$3))/'Thiessen Polygon Influence Zone'!$D$8 -> 118.21574 | N29: 6 | O29: 2018 | P29: 115 | Q29: 116 | R29: 119 | S29: 118.21574
C30: 2019 | D30: =((G11*$G$3)+(J11*$J$3)+(M11*$M$3))/'Thiessen Polygon Influence Zone'!$D$8 -> 131.31729 | N30: 7 | O30: 2019 | P30: 112 | Q30: 121 | R30: 136 | S30: 131.31729
C31: 2020 | D31: =((G12*$G$3)+(J12*$J$3)+(M12*$M$3))/'Thiessen Polygon Influence Zone'!$D$8 -> 165.30457 | N31: 8 | O31: 2020 | P31: 154 | Q31: 164 | R31: 168 | S31: 165.30457
C32: 2021 | D32: =((G13*$G$3)+(J13*$J$3)+(M13*$M$3))/'Thiessen Polygon Influence Zone'!$D$8 -> 163.0608 | N32: 9 | O32: 2021 | P32: 200 | Q32: 194 | R32: 154 | S32: 163.0608
C33: 2022 | D33: =((G14*$G$3)+(J14*$J$3)+(M14*$M$3))/'Thiessen Polygon Influence Zone'!$D$8 -> 117.56857 | N33: 10 | O33: 2022 | P33: 112 | Q33: 106 | R33: 119 | S33: 117.56857
C34: 2023 | D34: =((G15*$G$3)+(J15*$J$3)+(M15*$M$3))/'Thiessen Polygon Influence Zone'!$D$8 -> 100.36545 | N34: 11 | O34: 2023 | P34: 89 | Q34: 107 | R34: 103 | S34: 100.36545
C35: 2024 | D35: =((G16*$G$3)+(J16*$J$3)+(M16*$M$3))/'Thiessen Polygon Influence Zone'!$D$8 -> 149.05844 | N35: 12 | O35: 2024 | P35: 129 | Q35: 130 | R35: 154 | S35: 149.05844
N39: No | O39: Years | P39: Rainfall (mm)
P40: Pontianak Kota Climatology Station | Q40: West Kalimantan Climatology Station | R40: Pontianak Maritime Meteorology Station
N41: 1 | O41: 2013 | P41: 112 | Q41: 84 | R41: 120
N42: 2 | O42: 2014 | P42: 155 | Q42: 109 | R42: 150
N43: 3 | O43: 2015 | P43: 79 | Q43: 66 | R43: 87
N44: 4 | O44: 2016 | P44: 85 | Q44: 70 | R44: 87
N45: 5 | O45: 2017 | P45: 165 | Q45: 111 | R45: 102
N46: 6 | O46: 2018 | P46: 115 | Q46: 116 | R46: 119
N47: 7 | O47: 2019 | P47: 112 | Q47: 121 | R47: 136
N48: 8 | O48: 2020 | P48: 154 | Q48: 164 | R48: 168
...

Sheet Input Data
A1: No | B1: Year | C1: Curah Hujan (mm) | D1: MAX | E1: Sort
A2: 1 | B2: 2013 | C2: 118.20319 | D2: =MAX(C2:C13) -> 165.30457 | E2: 85.317338
A3: 2 | B3: 2014 | C3: 150.63978 | E3: 86.489918
A4: 3 | B4: 2015 | C4: 85.317338 | E4: 100.36545
A5: 4 | B5: 2016 | C5: 86.489918 | E5: 114.06096
A6: 5 | B6: 2017 | C6: 114.06096 | E6: 117.56857
A7: 6 | B7: 2018 | C7: 118.21574 | E7: 118.20319
A8: 7 | B8: 2019 | C8: 131.31729 | E8: 118.21574
A9: 8 | B9: 2020 | C9: 165.30457 | E9: 131.31729
A10: 9 | B10: 2021 | C10: 163.0608 | E10: 149.05844
A11: 10 | B11: 2022 | C11: 117.56857 | E11: 150.63978
A12: 11 | B12: 2023 | C12: 100.36545 | E12: 163.0608
A13: 12 | B13: 2024 | C13: 149.05844 | E13: 165.30457

Sheet Statistical Parameters
A2: Statistical Parameters of the Log-Pearson Type III Distribution
A3: No | B3: Ri (mm) | C3: log Ri | D3: log Ri - log Ri | E3: (log Ri - log Ri)2 | F3: (log Ri - log Ri)3 | G3: (log Ri - log Ri)4
A4: 1 | B4: 85.317338 | C4: =LOG(B4) -> 1.9310373 | D4: =C4-$C$28 -> -0.15584373 | E4: =D4^2 -> 0.024287269 | F4: =D4^3 -> -0.0037850188 | G4: =D4^4 -> 0.00058987146
A5: 2 | B5: 86.489918 | C5: =LOG(B5) -> 1.9369655 | D5: =C5-$C$28 -> -0.14991555 | E5: =D5^2 -> 0.022474671 | F5: =D5^3 -> -0.0033693026 | G5: =D5^4 -> 0.00050511084
A6: 3 | B6: 100.36545 | C6: =LOG(B6) -> 2.0015842 | D6: =C6-$C$28 -> -0.085296814 | E6: =D6^2 -> 0.0072755465 | F6: =D6^3 -> -0.00062058093 | G6: =D6^4 -> 5.2933576e-05
A7: 4 | B7: 114.06096 | C7: =LOG(B7) -> 2.057137 | D7: =C7-$C$28 -> -0.029744008 | E7: =D7^2 -> 0.00088470599 | F7: =D7^3 -> -2.6314702e-05 | G7: =D7^4 -> 7.8270468e-07
A8: 5 | B8: 117.56857 | C8: =LOG(B8) -> 2.0702913 | D8: =C8-$C$28 -> -0.016589781 | E8: =D8^2 -> 0.00027522082 | F8: =D8^3 -> -4.5658531e-06 | G8: =D8^4 -> 7.5746501e-08
A9: 6 | B9: 118.20319 | C9: =LOG(B9) -> 2.0726292 | D9: =C9-$C$28 -> -0.014251836 | E9: =D9^2 -> 0.00020311484 | F9: =D9^3 -> -2.8947594e-06 | G9: =D9^4 -> 4.1255637e-08
A10: 7 | B10: 118.21574 | C10: =LOG(B10) -> 2.0726753 | D10: =C10-$C$28 -> -0.014205715 | E10: =D10^2 -> 0.00020180233 | F10: =D10^3 -> -2.8667462e-06 | G10: =D10^4 -> 4.0724179e-08
A11: 8 | B11: 131.31729 | C11: =LOG(B11) -> 2.1183219 | D11: =C11-$C$28 -> 0.031440882 | E11: =D11^2 -> 0.00098852904 | F11: =D11^3 -> 3.1080225e-05 | G11: =D11^4 -> 9.7718966e-07
A12: 9 | B12: 149.05844 | C12: =LOG(B12) -> 2.1733566 | D12: =C12-$C$28 -> 0.086475554 | E12: =D12^2 -> 0.0074780214 | F12: =D12^3 -> 0.00064666604 | G12: =D12^4 -> 5.5920803e-05
A13: 10 | B13: 150.63978 | C13: =LOG(B13) -> 2.1779397 | D13: =C13-$C$28 -> 0.091058632 | E13: =D13^2 -> 0.0082916745 | F13: =D13^3 -> 0.00075502854 | G13: =D13^4 -> 6.8751866e-05
A14: 11 | B14: 163.0608 | C14: =LOG(B14) -> 2.2123496 | D14: =C14-$C$28 -> 0.12546855 | E14: =D14^2 -> 0.015742356 | F14: =D14^3 -> 0.0019751706 | G14: =D14^4 -> 0.00024782178
A15: 12 | B15: 165.30457 | C15: =LOG(B15) -> 2.2182849 | D15: =C15-$C$28 -> 0.13140382 | E15: =D15^2 -> 0.017266964 | F15: =D15^3 -> 0.002268945 | G15: =D15^4 -> 0.00029814803
A25: Jumlah | B25: =SUM(B4:B23) -> 1499.6021 | C25: =SUM(C4:C23) -> 25.042572 | D25: =SUM(D4:D15) -> -6.6613381e-16 | E25: =SUM(E4:E15) -> 0.10536988 | F25: =SUM(F4:F15) -> -0.002134654 | G25: =SUM(G4:G15) -> 0.001820476
A27: Rrata-rata | B27: = | C27: =AVERAGE(B4:B15) -> 124.96684
A28: log Rrata-rata | B28: = | C28: =AVERAGE(C4:C15) -> 2.086881
A29: Sd | B29: = | C29: =STDEV(C4:C15) -> 0.097872773
A30: Cv | B30: = | C30: =C29/C28 -> 0.046899067
A31: Cs | B31: = | C31: =SKEW(C4:C15) -> -0.24838787
A32: Ck | B32: = | C32: =((A15^2)/((A15-1)*(A15-2)*(A15-3)*(C29^4)))*G25 -> 2.8857897
B44: Cs = | C44: =(C30^3) + (3*C30) -> 0.14080036
B45: Ck = | C45: =(C30^8)+(6*(C30^6))+(15*(C30^4))+(16*(C30^2))+3 -> 3.035265

Sheet TABEL CS & G
B2: Tabel 20 Distribusi Log Pearson III untuk Koefisien Kemencengan (Cs)
B4: Koefisien | C4: Waktu Balik (Tahun)
C5: 1.010101 | D5: 1.0526316 | E5: 1.1111111 | F5: 1.25 | G5: 1.6666667 | H5: 2 | I5: 2.5 | J5: 5 | K5: 10 | L5: 20 | M5: 25 | N5: 50 | O5: 100 | P5: 200 | Q5: 1000
B6: Cs | C6: Peluang (%)
C7: 99 | D7: 95 | E7: 90 | F7: 80 | G7: 60 | H7: 50 | I7: 40 | J7: 20 | K7: 10 | L7: 5 | M7: 4 | N7: 2 | O7: 1 | P7: 0.5 | Q7: 0.1
B8: 3 | C8: -0.667 | D8: -0.665 | E8: -0.66 | F8: -0.636 | G8: -0.476 | H8: -0.396 | I8: -0.124 | J8: 0.42 | K8: 1.18 | L8: 2.095 | M8: 2.278 | N8: 3.152 | O8: 4.051 | P8: 4.97 | Q8: 7.25
B9: 2.5 | C9: -0.799 | D9: -0.79 | E9: -0.771 | F9: -0.711 | G9: -0.477 | H9: -0.36 | I9: -0.067333333 | J9: 0.518 | K9: 1.25 | L9: 2.0933333 | M9: 2.262 | N9: 3.048 | O9: 3.845 | P9: 4.652 | Q9: 6.6
B10: 2.2 | C10: -0.905 | D10: -0.882 | E10: -0.844 | F10: -0.752 | G10: -0.47066667 | H10: -0.33 | I10: -0.028666667 | J10: 0.574 | K10: 1.284 | L10: 2.0806667 | M10: 2.24 | N10: 2.97 | O10: 3.705 | P10: 4.444 | Q10: 6.2
B11: 2 | C11: -0.99 | D11: -0.949 | E11: -0.895 | F11: -0.777 | G11: -0.46366667 | H11: -0.307 | I11: -0.0016666667 | J11: 0.609 | K11: 1.302 | L11: 2.0661667 | M11: 2.219 | N11: 2.912 | O11: 3.605 | P11: 4.298 | Q11: 5.91
B12: 1.8 | C12: -1.087 | D12: -1.02 | E12: -0.945 | F12: -0.799 | G12: -0.45433333 | H12: -0.282 | I12: 0.026333333 | J12: 0.643 | K12: 1.318 | L12: 2.0471667 | M12: 2.193 | N12: 2.848 | O12: 3.499 | P12: 4.147 | Q12: 5.66
B13: 1.6 | C13: -1.197 | D13: -1.093 | E13: -0.994 | F13: -0.817 | G13: -0.44166667 | H13: -0.254 | I13: 0.055666667 | J13: 0.675 | K13: 1.329 | L13: 2.024 | M13: 2.163 | N13: 2.78 | O13: 3.388 | P13: 3.99 | Q13: 5.39
B14: 1.4 | C14: -1.318 | D14: -1.168 | E14: -1.041 | F14: -0.832 | G14: -0.42733333 | H14: -0.225 | I14: 0.085 | J14: 0.705 | K14: 1.337 | L14: 1.9961667 | M14: 2.128 | N14: 2.706 | O14: 3.271 | P14: 3.828 | Q14: 5.11
B15: 1.2 | C15: -1.449 | D15: -1.243 | E15: -1.086 | F15: -0.844 | G15: -0.41133333 | H15: -0.195 | I15: 0.114 | J15: 0.732 | K15: 1.34 | L15: 1.9625 | M15: 2.087 | N15: 2.626 | O15: 3.149 | P15: 3.661 | Q15: 4.82
B16: 1 | C16: -1.588 | D16: -1.317 | E16: -1.128 | F16: -0.852 | G16: -0.39333333 | H16: -0.164 | I16: 0.14333333 | J16: 0.758 | K16: 1.34 | L16: 1.9258333 | M16: 2.043 | N16: 2.542 | O16: 3.022 | P16: 3.489 | Q16: 4.54
B17: 0.9 | C17: -1.66 | D17: -1.353 | E17: -1.147 | F17: -0.854 | G17: -0.38333333 | H17: -0.148 | I17: 0.15766667 | J17: 0.769 | K17: 1.339 | L17: 1.9048333 | M17: 2.018 | N17: 2.498 | O17: 2.957 | P17: 3.401 | Q17: 4.395
B18: 0.8 | C18: -1.733 | D18: -1.388 | E18: -1.116 | F18: -0.856 | G18: -0.37333333 | H18: -0.132 | I18: 0.172 | J18: 0.78 | K18: 1.336 | L18: 1.8876667 | M18: 1.998 | N18: 2.453 | O18: 2.891 | P18: 3.312 | Q18: 4.25
B19: 0.7 | C19: -1.806 | D19: -1.423 | E19: -1.183 | F19: -0.857 | G19: -0.363 | H19: -0.116 | I19: 0.186 | J19: 0.79 | K19: 1.333 | L19: 1.8613333 | M19: 1.967 | N19: 2.407 | O19: 2.824 | P19: 3.223 | Q19: 4.105
... B44: -3 | C44: -4.051 | D44: -2.003 | E44: -1.18 | F44: -0.42 | G44: 0.124 | H44: 0.396 | I44: 0.476 | J44: 0.636 | K44: 0.66 | L44: 0.665 | M44: 0.666 | N44: 0.666 | O44: 0.667 | P44: 0.667 | Q44: 0.668
B45: Dikutip dari Ir. CD. Soemarto, B.I.E. Dipl. HE / Hidrologi Teknik
H49: OK

Sheet Design Rainfall
A3: Design Rainfall log pearson III
A6: Tahun rencana | B6: log R | C6: Sd | D6: Cs | E6: KT | F6: Log RT | G6: RT
A7: (T) | B7: (mm) | C7: (mm) | F7: (mm) | G7: (mm)
A8: 2 | B8: ='Statistical Parameters'!C28 -> 2.086881 | C8: ='Statistical Parameters'!C29 -> 0.097872773 | D8: ='Statistical Parameters'!C31 -> -0.24838787 | E8: =FORECAST(D$8,K13:K14,J13:J14) -> 0.041225938 | F8: =B$8+C$8*E8 -> 2.0909159 | G8: =10^F8 -> 123.28662
A9: 5 | E9: =FORECAST(D$8,L13:L14,J13:J14) -> 0.85145164 | F9: =B$8+C$8*E9 -> 2.170215 | G9: =10^F9 -> 147.98407
A10: 10 | E10: =FORECAST(D$8,M13:M14,J13:J14) -> 1.2517096 | F10: =B$8+C$8*E10 -> 2.2093893 | G10: =10^F10 -> 161.95312 | J10: Cs | K10: 2 | L10: 5 | M10: 10 | N10: 20 | O10: 25 | P10: 50 | Q10: 100
A11: 20 | E11: =FORECAST(D$8,N13:N14,J13:J14) -> 1.5936987 | F11: =B$8+C$8*E11 -> 2.2428607 | G11: =10^F11 -> 174.92857
A12: 25 | E12: =FORECAST(D$8,O13:O14,J13:J14) -> 1.6620965 | F12: =B$8+C$8*E12 -> 2.249555 | G12: =10^F12 -> 177.64583
A13: 50 | E13: =FORECAST(D$8,P13:P14,J13:J14) -> 1.9183867 | F13: =B$8+C$8*E13 -> 2.2746389 | G13: =10^F13 -> 188.20834 | J13: -0.2 | K13: 0.033 | L13: 0.85 | M13: 1.258 | N13: 1.6096667 | O13: 1.68 | P13: 1.945 | Q13: 2.178
A14: 100 | E14: =FORECAST(D$8,Q13:Q14,J13:J14) -> 2.142193 | F14: =B$8+C$8*E14 -> 2.2965434 | G14: =10^F14 -> 197.94448 | J14: -0.3 | K14: 0.05 | L14: 0.853 | M14: 1.245 | N14: 1.5766667 | O14: 1.643 | P14: 1.89 | Q14: 2.104
H18: Year | J18: RT
J19: (mm)
H20: 2 | J20: 123.28662
H21: 5 | J21: 147.98407
H22: 10 | J22: 161.95312
H23: 20 | J23: 174.92857
H24: 25 | J24: 177.64583
H25: 50 | J25: 188.20834
H26: 100 | J26: 197.94448
C33: Return Period (years) | D33: RT (mm) | E33: RT With RCP 2.6 (mm) | F33: RT With RCP 4.5 (mm) | G33: RT With RCP 8.5 (mm)
C34: 2 | D34: 123.287 | E34: 129.451 | F34: 135.616 | G34: 147.944
C35: 5 | D35: 147.984 | E35: 155.383 | F35: 162.782 | G35: 177.58
C36: 10 | D36: 161.953 | E36: 170.051 | F36: 177.148 | G36: 194.343
C37: 20 | D37: 174.929 | E37: 183.676 | F37: 192.422 | G37: 209.915
C38: 25 | D38: 177.646 | E38: 186.528 | F38: 195.411 | G38: 213.175
C39: 50 | D39: 188.208 | E39: 197.618 | F39: 207.029 | G39: 225.85
C40: 100 | D40: 197.944 | E40: 207.841 | F40: 217.738 | G40: 237.532

Sheet ABM
B2: Normal Condition | L2: RCP 2.6 | V2: RCP 4.5 | AF2: RCP 8.5
C3: ABM Method 2 Year Return Period | G3: P2 = | I3: ='[6]Design Rainfall'!D34 -> 123.287 | M3: ABM Method 2 Year Return Period | Q3: P2 = | S3: ='[6]Design Rainfall'!E34 -> 129.451 | W3: ABM Method 2 Year Return Period | AA3: P2 = | AC3: ='[6]Design Rainfall'!F34 -> 135.616 | AG3: ABM Method 2 Year Return Period | AK3: P2 = | AM3: ='[6]Design Rainfall'!G34 -> 147.944
B5: T (jam) | C5: Dt (jam) | D5: It (mm/jam) | E5: It T (mm) | F5: Dp (mm) | G5: Pt (%) | H5: hyetograph | L5: T (jam) | M5: Dt (jam) | N5: It (mm/jam) | O5: It T (mm) | P5: Dp (mm) | Q5: Pt (%) | R5: hyetograph | V5: T (jam) | W5: Dt (jam) | X5: It (mm/jam) | Y5: It T (mm) | Z5: Dp (mm) | AA5: Pt (%) | AB5: hyetograph | AF5: T (jam) | AG5: Dt (jam) | AH5: It (mm/jam) | AI5: It T (mm) | AJ5: Dp (mm) | AK5: Pt (%) | AL5: hyetograph
H6: % | I6: (mm) | R6: % | S6: (mm) | AB6: % | AC6: (mm) | AL6: % | AM6: (mm)
B7: 1 | C7: 0 1 | D7: =($I$3/24)*((24/B7)^(2/3)) -> 42.741216 | E7: =D7*B7 -> 42.741216 | F7: =E7 -> 42.741216 | G7: =(F7*100)/$F$19 -> 43.679023 | H7: =G18 -> 2.8587219 | I7: =(H7*$I$3)/100 -> 3.5244325 | L7: 1 | M7: 0 1 | N7: =($S$3/24)*((24/L7)^(2/3)) -> 44.878155 | O7: =N7*L7 -> 44.878155 | P7: =O7 -> 44.878155 | Q7: =(P7*100)/$P$19 -> 43.679023 | R7: =Q18 -> 2.8587219 | S7: =(R7*$S$3)/100 -> 3.7006441 | V7: 1 | W7: 0 1 | X7: =($AC$3/24)*((24/V7)^(2/3)) -> 47.015441 | Y7: =X7*V7 -> 47.015441 | Z7: =Y7 -> 47.015441 | AA7: =(Z7*100)/$Z$19 -> 43.679023 | AB7: =AA18 -> 2.8587219 | AC7: =(AB7*$AC$3)/100 -> 3.8768844 | AF7: 1 | AG7: 0 1 | AH7: =($AM$3/24)*((24/AF7)^(2/3)) -> 51.28932 | AI7: =AH7*AF7 -> 51.28932 | AJ7: =AI7 -> 51.28932 | AK7: =(AJ7*100)/$AJ$19 -> 43.679023 | AL7: =AK18 -> 2.8587219 | AM7: =(AL7*$AM$3)/100 -> 4.2293076
B8: 2 | C8: 1 2 | D8: =($I$3/24)*((24/B8)^(2/3)) -> 26.925279 | E8: =D8*B8 -> 53.850557 | F8: =E8-E7 -> 11.109342 | G8: =(F8*100)/$F$19 -> 11.353098 | H8: =G16 -> 3.2475732 | I8: =(H8*$I$3)/100 -> 4.0038356 | L8: 2 | M8: 1 2 | N8: =($S$3/24)*((24/L8)^(2/3)) -> 28.271466 | O8: =N8*L8 -> 56.542932 | P8: =O8-O7 -> 11.664777 | Q8: =(P8*100)/$P$19 -> 11.353098 | R8: =Q16 -> 3.2475732 | S8: =(R8*$S$3)/100 -> 4.204016 | V8: 2 | W8: 1 2 | X8: =($AC$3/24)*((24/V8)^(2/3)) -> 29.617872 | Y8: =X8*V8 -> 59.235744 | Z8: =Y8-Y7 -> 12.220303 | AA8: =(Z8*100)/$Z$19 -> 11.353098 | AB8: =AA16 -> 3.2475732 | AC8: =(AB8*$AC$3)/100 -> 4.4042289 | AF8: 2 | AG8: 1 2 | AH8: =($AM$3/24)*((24/AF8)^(2/3)) -> 32.310247 | AI8: =AH8*AF8 -> 64.620494 | AJ8: =AI8-AI7 -> 13.331174 | AK8: =(AJ8*100)/$AJ$19 -> 11.353098 | AL8: =AK16 -> 3.2475732 | AM8: =(AL8*$AM$3)/100 -> 4.8045898
B9: 3 | C9: 2 3 | D9: =($I$3/24)*((24/B9)^(2/3)) -> 20.547833 | E9: =D9*B9 -> 61.6435 | F9: =E9-E8 -> 7.7929426 | G9: =(F9*100)/$F$19 -> 7.9639317 | H9: =G14 -> 3.8030809 | I9: =(H9*$I$3)/100 -> 4.6887043 | L9: 3 | M9: 2 3 | N9: =($S$3/24)*((24/L9)^(2/3)) -> 21.575167 | O9: =N9*L9 -> 64.7255 | P9: =O9-O8 -> 8.1825676 | Q9: =(P9*100)/$P$19 -> 7.9639317 | R9: =Q14 -> 3.8030809 | S9: =(R9*$S$3)/100 -> 4.9231262 | V9: 3 | W9: 2 3 | X9: =($AC$3/24)*((24/V9)^(2/3)) -> 22.602667 | Y9: =X9*V9 -> 67.808 | Z9: =Y9-Y8 -> 8.5722558 | AA9: =(Z9*100)/$Z$19 -> 7.9639317 | AB9: =AA14 -> 3.8030809 | AC9: =(AB9*$AC$3)/100 -> 5.1575862 | AF9: 3 | AG9: 2 3 | AH9: =($AM$3/24)*((24/AF9)^(2/3)) -> 24.657333 | AI9: =AH9*AF9 -> 73.972 | AJ9: =AI9-AI8 -> 9.3515059 | AK9: =(AJ9*100)/$AJ$19 -> 7.9639317 | AL9: =AK14 -> 3.8030809 | AM9: =(AL9*$AM$3)/100 -> 5.62643
B10: 4 | C10: 3 4 | D10: =($I$3/24)*((24/B10)^(2/3)) -> 16.961863 | E10: =D10*B10 -> 67.847451 | F10: =E10-E9 -> 6.2039508 | G10: =(F10*100)/$F$19 -> 6.3400749 | H10: =G12 -> 4.6799735 | I10: =(H10*$I$3)/100 -> 5.7697989 | L10: 4 | M10: 3 4 | N10: =($S$3/24)*((24/L10)^(2/3)) -> 17.809908 | O10: =N10*L10 -> 71.239631 | P10: =O10-O9 -> 6.5141307 | Q10: =(P10*100)/$P$19 -> 6.3400749 | R10: =Q12 -> 4.6799735 | S10: =(R10*$S$3)/100 -> 6.0582725 | V10: 4 | W10: 3 4 | X10: =($AC$3/24)*((24/V10)^(2/3)) -> 18.65809 | Y10: =X10*V10 -> 74.632361 | Z10: =Y10-Y9 -> 6.824361 | AA10: =(Z10*100)/$Z$19 -> 6.3400749 | AB10: =AA12 -> 4.6799735 | AC10: =(AB10*$AC$3)/100 -> 6.3467928 | AF10: 4 | AG10: 3 4 | AH10: =($AM$3/24)*((24/AF10)^(2/3)) -> 20.35418 | AI10: =AH10*AF10 -> 81.416721 | AJ10: =AI10-AI9 -> 7.4447208 | AK10: =(AJ10*100)/$AJ$19 -> 6.3400749 | AL10: =AK12 -> 4.6799735 | AM10: =(AL10*$AM$3)/100 -> 6.92374
B11: 5 | C11: 4 5 | D11: =($I$3/24)*((24/B11)^(2/3)) -> 14.61729 | E11: =D11*B11 -> 73.086451 | F11: =E11-E10 -> 5.239 | G11: =(F11*100)/$F$19 -> 5.3539517 | H11: =G10 -> 6.3400749 | I11: =(H11*$I$3)/100 -> 7.8164882 | L11: 5 | M11: 4 5 | N11: =($S$3/24)*((24/L11)^(2/3)) -> 15.348113 | O11: =N11*L11 -> 76.740566 | P11: =O11-O10 -> 5.5009351 | Q11: =(P11*100)/$P$19 -> 5.3539517 | R11: =Q10 -> 6.3400749 | S11: =(R11*$S$3)/100 -> 8.2072904 | V11: 5 | W11: 4 5 | X11: =($AC$3/24)*((24/V11)^(2/3)) -> 16.079055 | Y11: =X11*V11 -> 80.395274 | Z11: =Y11-Y10 -> 5.7629128 | AA11: =(Z11*100)/$Z$19 -> 5.3539517 | AB11: =AA10 -> 6.3400749 | AC11: =(AB11*$AC$3)/100 -> 8.598156 | AF11: 5 | AG11: 4 5 | AH11: =($AM$3/24)*((24/AF11)^(2/3)) -> 17.540701 | AI11: =AH11*AF11 -> 87.703504 | AJ11: =AI11-AI10 -> 6.286783 | AK11: =(AJ11*100)/$AJ$19 -> 5.3539517 | AL11: =AK10 -> 6.3400749 | AM11: =(AL11*$AM$3)/100 -> 9.3797605
B12: 6 | C12: 5 6 | D12: =($I$3/24)*((24/B12)^(2/3)) -> 12.944324 | E12: =D12*B12 -> 77.665943 | F12: =E12-E11 -> 4.5794924 | G12: =(F12*100)/$F$19 -> 4.6799735 | H12: =G8 -> 11.353098 | I12: =(H12*$I$3)/100 -> 13.996893 | L12: 6 | M12: 5 6 | N12: =($S$3/24)*((24/L12)^(2/3)) -> 13.591503 | O12: =N12*L12 -> 81.54902 | P12: =O12-O11 -> 4.8084541 | Q12: =(P12*100)/$P$19 -> 4.6799735 | R12: =Q8 -> 11.353098 | S12: =(R12*$S$3)/100 -> 14.696698 | V12: 6 | W12: 5 6 | X12: =($AC$3/24)*((24/V12)^(2/3)) -> 14.238788 | Y12: =X12*V12 -> 85.432727 | Z12: =Y12-Y11 -> 5.0374528 | AA12: =(Z12*100)/$Z$19 -> 4.6799735 | AB12: =AA8 -> 11.353098 | AC12: =(AB12*$AC$3)/100 -> 15.396617 | AF12: 6 | AG12: 5 6 | AH12: =($AM$3/24)*((24/AF12)^(2/3)) -> 15.533147 | AI12: =AH12*AF12 -> 93.19888 | AJ12: =AI12-AI11 -> 5.4953761 | AK12: =(AJ12*100)/$AJ$19 -> 4.6799735 | AL12: =AK8 -> 11.353098 | AM12: =(AL12*$AM$3)/100 -> 16.796227
B13: 7 | C13: 6 7 | D13: =($I$3/24)*((24/B13)^(2/3)) -> 11.680143 | E13: =D13*B13 -> 81.761004 | F13: =E13-E12 -> 4.0950611 | G13: =(F13*100)/$F$19 -> 4.184913 | H13: =G7 -> 43.679023 | I13: =(H13*$I$3)/100 -> 53.850557 | L13: 7 | M13: 6 7 | N13: =($S$3/24)*((24/L13)^(2/3)) -> 12.264117 | O13: =N13*L13 -> 85.848822 | P13: =O13-O12 -> 4.2998025 | Q13: =(P13*100)/$P$19 -> 4.184913 | R13: =Q7 -> 43.679023 | S13: =(R13*$S$3)/100 -> 56.542932 | V13: 7 | W13: 6 7 | X13: =($AC$3/24)*((24/V13)^(2/3)) -> 12.848186 | Y13: =X13*V13 -> 89.937304 | Z13: =Y13-Y12 -> 4.5045772 | AA13: =(Z13*100)/$Z$19 -> 4.184913 | AB13: =AA7 -> 43.679023 | AC13: =(AB13*$AC$3)/100 -> 59.235744 | AF13: 7 | AG13: 6 7 | AH13: =($AM$3/24)*((24/AF13)^(2/3)) -> 14.016134 | AI13: =AH13*AF13 -> 98.11294 | AJ13: =AI13-AI12 -> 4.91406 | AK13: =(AJ13*100)/$AJ$19 -> 4.184913 | AL13: =AK7 -> 43.679023 | AM13: =(AL13*$AM$3)/100 -> 64.620494
B14: 8 | C14: 7 8 | D14: =($I$3/24)*((24/B14)^(2/3)) -> 10.685304 | E14: =D14*B14 -> 85.482431 | F14: =E14-E13 -> 3.7214271 | G14: =(F14*100)/$F$19 -> 3.8030809 | H14: =G9 -> 7.9639317 | I14: =(H14*$I$3)/100 -> 9.8184925 | L14: 8 | M14: 7 8 | N14: =($S$3/24)*((24/L14)^(2/3)) -> 11.219539 | O14: =N14*L14 -> 89.75631 | P14: =O14-O13 -> 3.9074879 | Q14: =(P14*100)/$P$19 -> 3.8030809 | R14: =Q9 -> 7.9639317 | S14: =(R14*$S$3)/100 -> 10.309389 | V14: 8 | W14: 7 8 | X14: =($AC$3/24)*((24/V14)^(2/3)) -> 11.75386 | Y14: =X14*V14 -> 94.030883 | Z14: =Y14-Y13 -> 4.0935789 | AA14: =(Z14*100)/$Z$19 -> 3.8030809 | AB14: =AA9 -> 7.9639317 | AC14: =(AB14*$AC$3)/100 -> 10.800366 | AF14: 8 | AG14: 7 8 | AH14: =($AM$3/24)*((24/AF14)^(2/3)) -> 12.82233 | AI14: =AH14*AF14 -> 102.57864 | AJ14: =AI14-AI13 -> 4.4657004 | AK14: =(AJ14*100)/$AJ$19 -> 3.8030809 | AL14: =AK9 -> 7.9639317 | AM14: =(AL14*$AM$3)/100 -> 11.782159
B15: 9 | C15: 8 9 | D15: =($I$3/24)*((24/B15)^(2/3)) -> 9.8783679 | E15: =D15*B15 -> 88.905311 | F15: =E15-E14 -> 3.42288 | G15: =(F15*100)/$F$19 -> 3.4979832 | H15: =G11 -> 5.3539517 | I15: =(H15*$I$3)/100 -> 6.6007264 | L15: 9 | M15: 8 9 | N15: =($S$3/24)*((24/L15)^(2/3)) -> 10.372258 | O15: =N15*L15 -> 93.350325 | P15: =O15-O14 -> 3.5940142 | Q15: =(P15*100)/$P$19 -> 3.4979832 | R15: =Q11 -> 5.3539517 | S15: =(R15*$S$3)/100 -> 6.930744 | V15: 9 | W15: 8 9 | X15: =($AC$3/24)*((24/V15)^(2/3)) -> 10.866229 | Y15: =X15*V15 -> 97.796059 | Z15: =Y15-Y14 -> 3.7651763 | AA15: =(Z15*100)/$Z$19 -> 3.4979832 | AB15: =AA11 -> 5.3539517 | AC15: =(AB15*$AC$3)/100 -> 7.2608151 | AF15: 9 | AG15: 8 9 | AH15: =($AM$3/24)*((24/AF15)^(2/3)) -> 11.854009 | AI15: =AH15*AF15 -> 106.68609 | AJ15: =AI15-AI14 -> 4.1074448 | AK15: =(AJ15*100)/$AJ$19 -> 3.4979832 | AL15: =AK11 -> 5.3539517 | AM15: =(AL15*$AM$3)/100 -> 7.9208503
B16: 10 | C16: 9 10 | D16: =($I$3/24)*((24/B16)^(2/3)) -> 9.2083158 | E16: =D16*B16 -> 92.083158 | F16: =E16-E15 -> 3.1778464 | G16: =(F16*100)/$F$19 -> 3.2475732 | H16: =G13 -> 4.184913 | I16: =(H16*$I$3)/100 -> 5.1594537 | L16: 10 | M16: 9 10 | N16: =($S$3/24)*((24/L16)^(2/3)) -> 9.6687054 | O16: =N16*L16 -> 96.687054 | P16: =O16-O15 -> 3.3367297 | Q16: =(P16*100)/$P$19 -> 3.2475732 | R16: =Q13 -> 4.184913 | S16: =(R16*$S$3)/100 -> 5.4174117 | V16: 10 | W16: 9 10 | X16: =($AC$3/24)*((24/V16)^(2/3)) -> 10.12917 | Y16: =X16*V16 -> 101.2917 | Z16: =Y16-Y15 -> 3.4956388 | AA16: =(Z16*100)/$Z$19 -> 3.2475732 | AB16: =AA13 -> 4.184913 | AC16: =(AB16*$AC$3)/100 -> 5.6754116 | AF16: 10 | AG16: 9 10 | AH16: =($AM$3/24)*((24/AF16)^(2/3)) -> 11.049949 | AI16: =AH16*AF16 -> 110.49949 | AJ16: =AI16-AI15 -> 3.8134054 | AK16: =(AJ16*100)/$AJ$19 -> 3.2475732 | AL16: =AK13 -> 4.184913 | AM16: =(AL16*$AM$3)/100 -> 6.1913277
B17: 11 | C17: 11 12 | D17: =($I$3/24)*((24/B17)^(2/3)) -> 8.6414193 | E17: =D17*B17 -> 95.055613 | F17: =E17-E16 -> 2.972455 | G17: =(F17*100)/$F$19 -> 3.0376752 | H17: =G15 -> 3.4979832 | I17: =(H17*$I$3)/100 -> 4.3125585 | L17: 11 | M17: 11 12 | N17: =($S$3/24)*((24/L17)^(2/3)) -> 9.0734658 | O17: =N17*L17 -> 99.808124 | P17: =O17-O16 -> 3.1210693 | Q17: =(P17*100)/$P$19 -> 3.0376752 | R17: =Q15 -> 3.4979832 | S17: =(R17*$S$3)/100 -> 4.5281742 | V17: 11 | W17: 11 12 | X17: =($AC$3/24)*((24/V17)^(2/3)) -> 9.5055823 | Y17: =X17*V17 -> 104.56141 | Z17: =Y17-Y16 -> 3.2697077 | AA17: =(Z17*100)/$Z$19 -> 3.0376752 | AB17: =AA15 -> 3.4979832 | AC17: =(AB17*$AC$3)/100 -> 4.7438249 | AF17: 11 | AG17: 11 12 | AH17: =($AM$3/24)*((24/AF17)^(2/3)) -> 10.369675 | AI17: =AH17*AF17 -> 114.06643 | AJ17: =AI17-AI16 -> 3.5669363 | AK17: =(AJ17*100)/$AJ$19 -> 3.0376752 | AL17: =AK15 -> 3.4979832 | AM17: =(AL17*$AM$3)/100 -> 5.1750562
B18: 12 | C18: 12 13 | D18: =($I$3/24)*((24/B18)^(2/3)) -> 8.1544131 | E18: =D18*B18 -> 97.852957 | F18: =E18-E17 -> 2.7973439 | G18: =(F18*100)/$F$19 -> 2.8587219 | H18: =G17 -> 3.0376752 | I18: =(H18*$I$3)/100 -> 3.7450586 | L18: 12 | M18: 12 13 | N18: =($S$3/24)*((24/L18)^(2/3)) -> 8.5621106 | O18: =N18*L18 -> 102.74533 | P18: =O18-O17 -> 2.9372032 | Q18: =(P18*100)/$P$19 -> 2.8587219 | R18: =Q17 -> 3.0376752 | S18: =(R18*$S$3)/100 -> 3.9323009 | V18: 12 | W18: 12 13 | X18: =($AC$3/24)*((24/V18)^(2/3)) -> 8.9698742 | Y18: =X18*V18 -> 107.63849 | Z18: =Y18-Y17 -> 3.0770852 | AA18: =(Z18*100)/$Z$19 -> 2.8587219 | AB18: =AA17 -> 3.0376752 | AC18: =(AB18*$AC$3)/100 -> 4.1195736 | AF18: 12 | AG18: 12 13 | AH18: =($AM$3/24)*((24/AF18)^(2/3)) -> 9.7852692 | AI18: =AH18*AF18 -> 117.42323 | AJ18: =AI18-AI17 -> 3.3568037 | AK18: =(AJ18*100)/$AJ$19 -> 2.8587219 | AL18: =AK17 -> 3.0376752 | AM18: =(AL18*$AM$3)/100 -> 4.4940581
B19: Total | F19: =SUM(F7:F18) -> 97.852957 | G19: =(F19*100)/$F$19 -> 100 | H19: =SUM(H7:H18) -> 100 | I19: =SUM(I7:I18) -> 123.287 | L19: Total | P19: =SUM(P7:P18) -> 102.74533 | Q19: =(P19*100)/$P$19 -> 100 | R19: =SUM(R7:R18) -> 100 | S19: =SUM(S7:S18) -> 129.451 | V19: Total | Z19: =SUM(Z7:Z18) -> 107.63849 | AA19: =(Z19*100)/$Z$19 -> 100 | AB19: =SUM(AB7:AB18) -> 100 | AC19: =SUM(AC7:AC18) -> 135.616 | AF19: Total | AJ19: =SUM(AJ7:AJ18) -> 117.42323 | AK19: =(AJ19*100)/$AJ$19 -> 100 | AL19: =SUM(AL7:AL18) -> 100 | AM19: =SUM(AM7:AM18) -> 147.944
C22: ABM Method 5 Year Return Period | G22: P5 = | I22: ='[6]Design Rainfall'!D35 -> 147.984 | M22: ABM Method 5 Year Return Period | Q22: P5 = | S22: ='[6]Design Rainfall'!E35 -> 155.383 | W22: ABM Method 5 Year Return Period | AA22: P5 = | AC22: ='[6]Design Rainfall'!F35 -> 162.782 | AG22: ABM Method 5 Year Return Period | AK22: P5 = | AM22: ='[6]Design Rainfall'!G35 -> 177.58
B24: T (jam) | C24: Dt (jam) | D24: It (mm/jam) | E24: It T (mm) | F24: Dp (mm) | G24: Pt (%) | H24: hyetograph | L24: T (jam) | M24: Dt (jam) | N24: It (mm/jam) | O24: It T (mm) | P24: Dp (mm) | Q24: Pt (%) | R24: hyetograph | V24: T (jam) | W24: Dt (jam) | X24: It (mm/jam) | Y24: It T (mm) | Z24: Dp (mm) | AA24: Pt (%) | AB24: hyetograph | AF24: T (jam) | AG24: Dt (jam) | AH24: It (mm/jam) | AI24: It T (mm) | AJ24: Dp (mm) | AK24: Pt (%) | AL24: hyetograph
H25: % | I25: (mm) | R25: % | S25: (mm) | AB25: % | AC25: (mm) | AL25: % | AM25: (mm)
B26: 1 | C26: 0 1 | D26: =($I$22/24)*((24/B26)^(2/3)) -> 51.303187 | E26: =D26*B26 -> 51.303187 | F26: =E26 -> 51.303187 | G26: =(F26*100)/$F$38 -> 43.679023 | H26: =G37 -> 2.8587219 | I26: =(H26*$I$22)/100 -> 4.2304511 | L26: 1 | M26: 0 1 | N26: =($S$22/24)*((24/L26)^(2/3)) -> 53.868277 | O26: =N26*L26 -> 53.868277 | P26: =O26 -> 53.868277 | Q26: =(P26*100)/$P$38 -> 43.679023 | R26: =Q37 -> 2.8587219 | S26: =(R26*$S$22)/100 -> 4.4419679 | V26: 1 | W26: 0 1 | X26: =($AC$22/24)*((24/V26)^(2/3)) -> 56.433367 | Y26: =X26*V26 -> 56.433367 | Z26: =Y26 -> 56.433367 | AA26: =(Z26*100)/$Z$38 -> 43.679023 | AB26: =AA37 -> 2.8587219 | AC26: =(AB26*$AC$22)/100 -> 4.6534848 | AF26: 1 | AG26: 0 1 | AH26: =($AM$22/24)*((24/AF26)^(2/3)) -> 61.563548 | AI26: =AH26*AF26 -> 61.563548 | AJ26: =AI26 -> 61.563548 | AK26: =(AJ26*100)/$AJ$38 -> 43.679023 | AL26: =AK37 -> 2.8587219 | AM26: =(AL26*$AM$22)/100 -> 5.0765184
B27: 2 | C27: 1 2 | D27: =($I$22/24)*((24/B27)^(2/3)) -> 32.318983 | E27: =D27*B27 -> 64.637966 | F27: =E27-E26 -> 13.334778 | G27: =(F27*100)/$F$38 -> 11.353098 | H27: =G35 -> 3.2475732 | I27: =(H27*$I$22)/100 -> 4.8058888 | L27: 2 | M27: 1 2 | N27: =($S$22/24)*((24/L27)^(2/3)) -> 33.934888 | O27: =N27*L27 -> 67.869777 | P27: =O27-O26 -> 14.001499 | Q27: =(P27*100)/$P$38 -> 11.353098 | R27: =Q35 -> 3.2475732 | S27: =(R27*$S$22)/100 -> 5.0461767 | V27: 2 | W27: 1 2 | X27: =($AC$22/24)*((24/V27)^(2/3)) -> 35.550794 | Y27: =X27*V27 -> 71.101588 | Z27: =Y27-Y26 -> 14.66822 | AA27: =(Z27*100)/$Z$38 -> 11.353098 | AB27: =AA35 -> 3.2475732 | AC27: =(AB27*$AC$22)/100 -> 5.2864647 | AF27: 2 | AG27: 1 2 | AH27: =($AM$22/24)*((24/AF27)^(2/3)) -> 38.782605 | AI27: =AH27*AF27 -> 77.565209 | AJ27: =AI27-AI26 -> 16.001662 | AK27: =(AJ27*100)/$AJ$38 -> 11.353098 | AL27: =AK35 -> 3.2475732 | AM27: =(AL27*$AM$22)/100 -> 5.7670406
B28: 3 | C28: 2 3 | D28: =($I$22/24)*((24/B28)^(2/3)) -> 24.664 | E28: =D28*B28 -> 73.992 | F28: =E28-E27 -> 9.3540343 | G28: =(F28*100)/$F$38 -> 7.9639317 | H28: =G33 -> 3.8030809 | I28: =(H28*$I$22)/100 -> 5.6279512 | L28: 3 | M28: 2 3 | N28: =($S$22/24)*((24/L28)^(2/3)) -> 25.897167 | O28: =N28*L28 -> 77.6915 | P28: =O28-O27 -> 9.8217233 | Q28: =(P28*100)/$P$38 -> 7.9639317 | R28: =Q33 -> 3.8030809 | S28: =(R28*$S$22)/100 -> 5.9093412 | V28: 3 | W28: 2 3 | X28: =($AC$22/24)*((24/V28)^(2/3)) -> 27.130333 | Y28: =X28*V28 -> 81.391 | Z28: =Y28-Y27 -> 10.289412 | AA28: =(Z28*100)/$Z$38 -> 7.9639317 | AB28: =AA33 -> 3.8030809 | AC28: =(AB28*$AC$22)/100 -> 6.1907311 | AF28: 3 | AG28: 2 3 | AH28: =($AM$22/24)*((24/AF28)^(2/3)) -> 29.596667 | AI28: =AH28*AF28 -> 88.79 | AJ28: =AI28-AI27 -> 11.224791 | AK28: =(AJ28*100)/$AJ$38 -> 7.9639317 | AL28: =AK33 -> 3.8030809 | AM28: =(AL28*$AM$22)/100 -> 6.753511
B29: 4 | C29: 3 4 | D29: =($I$22/24)*((24/B29)^(2/3)) -> 20.359683 | E29: =D29*B29 -> 81.438734 | F29: =E29-E28 -> 7.4467337 | G29: =(F29*100)/$F$38 -> 6.3400749 | H29: =G31 -> 4.6799735 | I29: =(H29*$I$22)/100 -> 6.925612 | L29: 4 | M29: 3 4 | N29: =($S$22/24)*((24/L29)^(2/3)) -> 21.37764 | O29: =N29*L29 -> 85.51056 | P29: =O29-O28 -> 7.8190603 | Q29: =(P29*100)/$P$38 -> 6.3400749 | R29: =Q31 -> 4.6799735 | S29: =(R29*$S$22)/100 -> 7.2718832 | V29: 4 | W29: 3 4 | X29: =($AC$22/24)*((24/V29)^(2/3)) -> 22.395597 | Y29: =X29*V29 -> 89.582387 | Z29: =Y29-Y28 -> 8.1913869 | AA29: =(Z29*100)/$Z$38 -> 6.3400749 | AB29: =AA31 -> 4.6799735 | AC29: =(AB29*$AC$22)/100 -> 7.6181544 | AF29: 4 | AG29: 3 4 | AH29: =($AM$22/24)*((24/AF29)^(2/3)) -> 24.43151 | AI29: =AH29*AF29 -> 97.72604 | AJ29: =AI29-AI28 -> 8.9360401 | AK29: =(AJ29*100)/$AJ$38 -> 6.3400749 | AL29: =AK31 -> 4.6799735 | AM29: =(AL29*$AM$22)/100 -> 8.3106969
B30: 5 | C30: 4 5 | D30: =($I$22/24)*((24/B30)^(2/3)) -> 17.545443 | E30: =D30*B30 -> 87.727216 | F30: =E30-E29 -> 6.2884828 | G30: =(F30*100)/$F$38 -> 5.3539517 | H30: =G29 -> 6.3400749 | I30: =(H30*$I$22)/100 -> 9.3822965 | L30: 5 | M30: 4 5 | N30: =($S$22/24)*((24/L30)^(2/3)) -> 18.422692 | O30: =N30*L30 -> 92.113459 | P30: =O30-O29 -> 6.6028984 | Q30: =(P30*100)/$P$38 -> 5.3539517 | R30: =Q29 -> 6.3400749 | S30: =(R30*$S$22)/100 -> 9.8513986 | V30: 5 | W30: 4 5 | X30: =($AC$22/24)*((24/V30)^(2/3)) -> 19.29994 | Y30: =X30*V30 -> 96.499701 | Z30: =Y30-Y29 -> 6.9173141 | AA30: =(Z30*100)/$Z$38 -> 5.3539517 | AB30: =AA29 -> 6.3400749 | AC30: =(AB30*$AC$22)/100 -> 10.320501 | AF30: 5 | AG30: 4 5 | AH30: =($AM$22/24)*((24/AF30)^(2/3)) -> 21.054437 | AI30: =AH30*AF30 -> 105.27219 | AJ30: =AI30-AI29 -> 7.5461454 | AK30: =(AJ30*100)/$AJ$38 -> 5.3539517 | AL30: =AK29 -> 6.3400749 | AM30: =(AL30*$AM$22)/100 -> 11.258705
B31: 6 | C31: 5 6 | D31: =($I$22/24)*((24/B31)^(2/3)) -> 15.537346 | E31: =D31*B31 -> 93.224078 | F31: =E31-E30 -> 5.4968619 | G31: =(F31*100)/$F$38 -> 4.6799735 | H31: =G27 -> 11.353098 | I31: =(H31*$I$22)/100 -> 16.800768 | L31: 6 | M31: 5 6 | N31: =($S$22/24)*((24/L31)^(2/3)) -> 16.314193 | O31: =N31*L31 -> 97.885156 | P31: =O31-O30 -> 5.7716975 | Q31: =(P31*100)/$P$38 -> 4.6799735 | R31: =Q27 -> 11.353098 | S31: =(R31*$S$22)/100 -> 17.640784 | V31: 6 | W31: 5 6 | X31: =($AC$22/24)*((24/V31)^(2/3)) -> 17.091039 | Y31: =X31*V31 -> 102.54623 | Z31: =Y31-Y30 -> 6.0465332 | AA31: =(Z31*100)/$Z$38 -> 4.6799735 | AB31: =AA27 -> 11.353098 | AC31: =(AB31*$AC$22)/100 -> 18.480799 | AF31: 6 | AG31: 5 6 | AH31: =($AM$22/24)*((24/AF31)^(2/3)) -> 18.644732 | AI31: =AH31*AF31 -> 111.86839 | AJ31: =AI31-AI30 -> 6.5962045 | AK31: =(AJ31*100)/$AJ$38 -> 4.6799735 | AL31: =AK27 -> 11.353098 | AM31: =(AL31*$AM$22)/100 -> 20.160831
B32: 7 | C32: 6 7 | D32: =($I$22/24)*((24/B32)^(2/3)) -> 14.019924 | E32: =D32*B32 -> 98.139467 | F32: =E32-E31 -> 4.9153887 | G32: =(F32*100)/$F$38 -> 4.184913 | H32: =G26 -> 43.679023 | I32: =(H32*$I$22)/100 -> 64.637966 | L32: 7 | M32: 6 7 | N32: =($S$22/24)*((24/L32)^(2/3)) -> 14.720901 | O32: =N32*L32 -> 103.04631 | P32: =O32-O31 -> 5.1611514 | Q32: =(P32*100)/$P$38 -> 4.184913 | R32: =Q26 -> 43.679023 | S32: =(R32*$S$22)/100 -> 67.869777 | V32: 7 | W32: 6 7 | X32: =($AC$22/24)*((24/V32)^(2/3)) -> 15.421878 | Y32: =X32*V32 -> 107.95315 | Z32: =Y32-Y31 -> 5.4069142 | AA32: =(Z32*100)/$Z$38 -> 4.184913 | AB32: =AA26 -> 43.679023 | AC32: =(AB32*$AC$22)/100 -> 71.101588 | AF32: 7 | AG32: 6 7 | AH32: =($AM$22/24)*((24/AF32)^(2/3)) -> 16.823833 | AI32: =AH32*AF32 -> 117.76683 | AJ32: =AI32-AI31 -> 5.8984398 | AK32: =(AJ32*100)/$AJ$38 -> 4.184913 | AL32: =AK26 -> 43.679023 | AM32: =(AL32*$AM$22)/100 -> 77.565209
B33: 8 | C33: 7 8 | D33: =($I$22/24)*((24/B33)^(2/3)) -> 12.825797 | E33: =D33*B33 -> 102.60637 | F33: =E33-E32 -> 4.4669078 | G33: =(F33*100)/$F$38 -> 3.8030809 | H33: =G28 -> 7.9639317 | I33: =(H33*$I$22)/100 -> 11.785345 | L33: 8 | M33: 7 8 | N33: =($S$22/24)*((24/L33)^(2/3)) -> 13.467069 | O33: =N33*L33 -> 107.73655 | P33: =O33-O32 -> 4.6902472 | Q33: =(P33*100)/$P$38 -> 3.8030809 | R33: =Q28 -> 7.9639317 | S33: =(R33*$S$22)/100 -> 12.374596 | V33: 8 | W33: 7 8 | X33: =($AC$22/24)*((24/V33)^(2/3)) -> 14.108342 | Y33: =X33*V33 -> 112.86673 | Z33: =Y33-Y32 -> 4.9135866 | AA33: =(Z33*100)/$Z$38 -> 3.8030809 | AB33: =AA28 -> 7.9639317 | AC33: =(AB33*$AC$22)/100 -> 12.963847 | AF33: 8 | AG33: 7 8 | AH33: =($AM$22/24)*((24/AF33)^(2/3)) -> 15.390887 | AI33: =AH33*AF33 -> 123.1271 | AJ33: =AI33-AI32 -> 5.3602653 | AK33: =(AJ33*100)/$AJ$38 -> 3.8030809 | AL33: =AK28 -> 7.9639317 | AM33: =(AL33*$AM$22)/100 -> 14.14235
B34: 9 | C34: 8 9 | D34: =($I$22/24)*((24/B34)^(2/3)) -> 11.857214 | E34: =D34*B34 -> 106.71493 | F34: =E34-E33 -> 4.1085554 | G34: =(F34*100)/$F$38 -> 3.4979832 | H34: =G30 -> 5.3539517 | I34: =(H34*$I$22)/100 -> 7.9229918 | L34: 9 | M34: 8 9 | N34: =($S$22/24)*((24/L34)^(2/3)) -> 12.450059 | O34: =N34*L34 -> 112.05053 | P34: =O34-O33 -> 4.3139776 | Q34: =(P34*100)/$P$38 -> 3.4979832 | R34: =Q30 -> 5.3539517 | S34: =(R34*$S$22)/100 -> 8.3191307 | V34: 9 | W34: 8 9 | X34: =($AC$22/24)*((24/V34)^(2/3)) -> 13.042904 | Y34: =X34*V34 -> 117.38613 | Z34: =Y34-Y33 -> 4.5193998 | AA34: =(Z34*100)/$Z$38 -> 3.4979832 | AB34: =AA30 -> 5.3539517 | AC34: =(AB34*$AC$22)/100 -> 8.7152696 | AF34: 9 | AG34: 8 9 | AH34: =($AM$22/24)*((24/AF34)^(2/3)) -> 14.228593 | AI34: =AH34*AF34 -> 128.05734 | AJ34: =AI34-AI33 -> 4.9302442 | AK34: =(AJ34*100)/$AJ$38 -> 3.4979832 | AL34: =AK30 -> 5.3539517 | AM34: =(AL34*$AM$22)/100 -> 9.5075474
B35: 10 | C35: 9 10 | D35: =($I$22/24)*((24/B35)^(2/3)) -> 11.052937 | E35: =D35*B35 -> 110.52937 | F35: =E35-E34 -> 3.8144365 | G35: =(F35*100)/$F$38 -> 3.2475732 | H35: =G32 -> 4.184913 | I35: =(H35*$I$22)/100 -> 6.1930016 | L35: 10 | M35: 9 10 | N35: =($S$22/24)*((24/L35)^(2/3)) -> 11.605569 | O35: =N35*L35 -> 116.05569 | P35: =O35-O34 -> 4.0051531 | Q35: =(P35*100)/$P$38 -> 3.2475732 | R35: =Q32 -> 4.184913 | S35: =(R35*$S$22)/100 -> 6.5026433 | V35: 10 | W35: 9 10 | X35: =($AC$22/24)*((24/V35)^(2/3)) -> 12.1582 | Y35: =X35*V35 -> 121.582 | Z35: =Y35-Y34 -> 4.1958698 | AA35: =(Z35*100)/$Z$38 -> 3.2475732 | AB35: =AA32 -> 4.184913 | AC35: =(AB35*$AC$22)/100 -> 6.8122851 | AF35: 10 | AG35: 9 10 | AH35: =($AM$22/24)*((24/AF35)^(2/3)) -> 13.263464 | AI35: =AH35*AF35 -> 132.63464 | AJ35: =AI35-AI34 -> 4.5773031 | AK35: =(AJ35*100)/$AJ$38 -> 3.2475732 | AL35: =AK32 -> 4.184913 | AM35: =(AL35*$AM$22)/100 -> 7.4315685
B36: 11 | C36: 11 12 | D36: =($I$22/24)*((24/B36)^(2/3)) -> 10.372479 | E36: =D36*B36 -> 114.09727 | F36: =E36-E35 -> 3.5679007 | G36: =(F36*100)/$F$38 -> 3.0376752 | H36: =G34 -> 3.4979832 | I36: =(H36*$I$22)/100 -> 5.1764554 | L36: 11 | M36: 11 12 | N36: =($S$22/24)*((24/L36)^(2/3)) -> 10.891089 | O36: =N36*L36 -> 119.80198 | P36: =O36-O35 -> 3.7462909 | Q36: =(P36*100)/$P$38 -> 3.0376752 | R36: =Q34 -> 3.4979832 | S36: =(R36*$S$22)/100 -> 5.4352712 | V36: 11 | W36: 11 12 | X36: =($AC$22/24)*((24/V36)^(2/3)) -> 11.409699 | Y36: =X36*V36 -> 125.50669 | Z36: =Y36-Y35 -> 3.9246811 | AA36: =(Z36*100)/$Z$38 -> 3.0376752 | AB36: =AA34 -> 3.4979832 | AC36: =(AB36*$AC$22)/100 -> 5.694087 | AF36: 11 | AG36: 11 12 | AH36: =($AM$22/24)*((24/AF36)^(2/3)) -> 12.446919 | AI36: =AH36*AF36 -> 136.9161 | AJ36: =AI36-AI35 -> 4.2814616 | AK36: =(AJ36*100)/$AJ$38 -> 3.0376752 | AL36: =AK34 -> 3.4979832 | AM36: =(AL36*$AM$22)/100 -> 6.2117185
B37: 12 | C37: 12 13 | D37: =($I$22/24)*((24/B37)^(2/3)) -> 9.7879149 | E37: =D37*B37 -> 117.45498 | F37: =E37-E36 -> 3.3577113 | G37: =(F37*100)/$F$38 -> 2.8587219 | H37: =G36 -> 3.0376752 | I37: =(H37*$I$22)/100 -> 4.4952732 | L37: 12 | M37: 12 13 | N37: =($S$22/24)*((24/L37)^(2/3)) -> 10.277297 | O37: =N37*L37 -> 123.32757 | P37: =O37-O36 -> 3.5255923 | Q37: =(P37*100)/$P$38 -> 2.8587219 | R37: =Q36 -> 3.0376752 | S37: =(R37*$S$22)/100 -> 4.7200308 | V37: 12 | W37: 12 13 | X37: =($AC$22/24)*((24/V37)^(2/3)) -> 10.76668 | Y37: =X37*V37 -> 129.20016 | Z37: =Y37-Y36 -> 3.6934733 | AA37: =(Z37*100)/$Z$38 -> 2.8587219 | AB37: =AA36 -> 3.0376752 | AC37: =(AB37*$AC$22)/100 -> 4.9447884 | AF37: 12 | AG37: 12 13 | AH37: =($AM$22/24)*((24/AF37)^(2/3)) -> 11.745445 | AI37: =AH37*AF37 -> 140.94534 | AJ37: =AI37-AI36 -> 4.0292353 | AK37: =(AJ37*100)/$AJ$38 -> 2.8587219 | AL37: =AK36 -> 3.0376752 | AM37: =(AL37*$AM$22)/100 -> 5.3943036
B38: Total | F38: =SUM(F26:F37) -> 117.45498 | G38: =(F38*100)/$F$38 -> 100 | H38: =SUM(H26:H37) -> 100 | I38: =SUM(I26:I37) -> 147.984 | L38: Total | P38: =SUM(P26:P37) -> 123.32757 | Q38: =(P38*100)/$P$38 -> 100 | R38: =SUM(R26:R37) -> 100 | S38: =SUM(S26:S37) -> 155.383 | V38: Total | Z38: =SUM(Z26:Z37) -> 129.20016 | AA38: =(Z38*100)/$Z$38 -> 100 | AB38: =SUM(AB26:AB37) -> 100 | AC38: =SUM(AC26:AC37) -> 162.782 | AF38: Total | AJ38: =SUM(AJ26:AJ37) -> 140.94534 | AK38: =(AJ38*100)/$AJ$38 -> 100 | AL38: =SUM(AL26:AL37) -> 100 | AM38: =SUM(AM26:AM37) -> 177.58
C41: ABM Method 10 Year Return Period | G41: P10 = | I41: ='[6]Design Rainfall'!D36 -> 161.953 | M41: ABM Method 10 Year Return Period | Q41: P10 = | S41: ='[6]Design Rainfall'!E36 -> 170.051 | W41: ABM Method 10 Year Return Period | AA41: P10 = | AC41: ='[6]Design Rainfall'!F36 -> 177.148 | AG41: ABM Method 10 Year Return Period | AK41: P10 = | AM41: ='[6]Design Rainfall'!G36 -> 194.343
B43: T (jam) | C43: Dt (jam) | D43: It (mm/jam) | E43: It T (mm) | F43: Dp (mm) | G43: Pt (%) | H43: hyetograph | L43: T (jam) | M43: Dt (jam) | N43: It (mm/jam) | O43: It T (mm) | P43: Dp (mm) | Q43: Pt (%) | R43: hyetograph | V43: T (jam) | W43: Dt (jam) | X43: It (mm/jam) | Y43: It T (mm) | Z43: Dp (mm) | AA43: Pt (%) | AB43: hyetograph | AF43: T (jam) | AG43: Dt (jam) | AH43: It (mm/jam) | AI43: It T (mm) | AJ43: Dp (mm) | AK43: Pt (%) | AL43: hyetograph
H44: % | I44: (mm) | R44: % | S44: (mm) | AB44: % | AC44: (mm) | AL44: % | AM44: (mm)
B45: 1 | C45: 0 1 | D45: =($I$41/24)*((24/B45)^(2/3)) -> 56.145969 | E45: =D45*B45 -> 56.145969 | F45: =E45 -> 56.145969 | G45: =(F45*100)/$F$57 -> 43.679023 | H45: =G56 -> 2.8587219 | I45: =(H45*$I$41)/100 -> 4.629786 | L45: 1 | M45: 0 1 | N45: =($S$41/24)*((24/L45)^(2/3)) -> 58.953389 | O45: =N45*L45 -> 58.953389 | P45: =O45 -> 58.953389 | Q45: =(P45*100)/$P$57 -> 43.679023 | R45: =Q56 -> 2.8587219 | S45: =(R45*$S$41)/100 -> 4.8612853 | V45: 1 | W45: 0 1 | X45: =($AC$41/24)*((24/V45)^(2/3)) -> 61.413782 | Y45: =X45*V45 -> 61.413782 | Z45: =Y45 -> 61.413782 | AA45: =(Z45*100)/$Z$57 -> 43.679023 | AB45: =AA56 -> 2.8587219 | AC45: =(AB45*$AC$41)/100 -> 5.0641688 | AF45: 1 | AG45: 0 1 | AH45: =($AM$41/24)*((24/AF45)^(2/3)) -> 67.374955 | AI45: =AH45*AF45 -> 67.374955 | AJ45: =AI45 -> 67.374955 | AK45: =(AJ45*100)/$AJ$57 -> 43.679023 | AL45: =AK56 -> 2.8587219 | AM45: =(AL45*$AM$41)/100 -> 5.555726
B46: 2 | C46: 1 2 | D46: =($I$41/24)*((24/B46)^(2/3)) -> 35.369744 | E46: =D46*B46 -> 70.739489 | F46: =E46-E45 -> 14.593519 | G46: =(F46*100)/$F$57 -> 11.353098 | H46: =G54 -> 3.2475732 | I46: =(H46*$I$41)/100 -> 5.2595423 | L46: 2 | M46: 1 2 | N46: =($S$41/24)*((24/L46)^(2/3)) -> 37.138308 | O46: =N46*L46 -> 74.276616 | P46: =O46-O45 -> 15.323227 | Q46: =(P46*100)/$P$57 -> 11.353098 | R46: =Q54 -> 3.2475732 | S46: =(R46*$S$41)/100 -> 5.5225308 | V46: 2 | W46: 1 2 | X46: =($AC$41/24)*((24/V46)^(2/3)) -> 38.688258 | Y46: =X46*V46 -> 77.376516 | Z46: =Y46-Y45 -> 15.962735 | AA46: =(Z46*100)/$Z$57 -> 11.353098 | AB46: =AA54 -> 3.2475732 | AC46: =(AB46*$AC$41)/100 -> 5.7530111 | AF46: 2 | AG46: 1 2 | AH46: =($AM$41/24)*((24/AF46)^(2/3)) -> 42.443562 | AI46: =AH46*AF46 -> 84.887124 | AJ46: =AI46-AI45 -> 17.512169 | AK46: =(AJ46*100)/$AJ$57 -> 11.353098 | AL46: =AK54 -> 3.2475732 | AM46: =(AL46*$AM$41)/100 -> 6.3114313
B47: 3 | C47: 2 3 | D47: =($I$41/24)*((24/B47)^(2/3)) -> 26.992167 | E47: =D47*B47 -> 80.9765 | F47: =E47-E46 -> 10.237011 | G47: =(F47*100)/$F$57 -> 7.9639317 | H47: =G52 -> 3.8030809 | I47: =(H47*$I$41)/100 -> 6.1592036 | L47: 3 | M47: 2 3 | N47: =($S$41/24)*((24/L47)^(2/3)) -> 28.341833 | O47: =N47*L47 -> 85.0255 | P47: =O47-O46 -> 10.748884 | Q47: =(P47*100)/$P$57 -> 7.9639317 | R47: =Q52 -> 3.8030809 | S47: =(R47*$S$41)/100 -> 6.4671771 | V47: 3 | W47: 2 3 | X47: =($AC$41/24)*((24/V47)^(2/3)) -> 29.524667 | Y47: =X47*V47 -> 88.574 | Z47: =Y47-Y46 -> 11.197484 | AA47: =(Z47*100)/$Z$57 -> 7.9639317 | AB47: =AA52 -> 3.8030809 | AC47: =(AB47*$AC$41)/100 -> 6.7370817 | AF47: 3 | AG47: 2 3 | AH47: =($AM$41/24)*((24/AF47)^(2/3)) -> 32.3905 | AI47: =AH47*AF47 -> 97.1715 | AJ47: =AI47-AI46 -> 12.284376 | AK47: =(AJ47*100)/$AJ$57 -> 7.9639317 | AL47: =AK52 -> 3.8030809 | AM47: =(AL47*$AM$41)/100 -> 7.3910215
B48: 4 | C48: 3 4 | D48: =($I$41/24)*((24/B48)^(2/3)) -> 22.281543 | E48: =D48*B48 -> 89.126171 | F48: =E48-E47 -> 8.1496706 | G48: =(F48*100)/$F$57 -> 6.3400749 | H48: =G50 -> 4.6799735 | I48: =(H48*$I$41)/100 -> 7.5793575 | L48: 4 | M48: 3 4 | N48: =($S$41/24)*((24/L48)^(2/3)) -> 23.395668 | O48: =N48*L48 -> 93.582672 | P48: =O48-O47 -> 8.5571718 | Q48: =(P48*100)/$P$57 -> 6.3400749 | R48: =Q50 -> 4.6799735 | S48: =(R48*$S$41)/100 -> 7.9583417 | V48: 4 | W48: 3 4 | X48: =($AC$41/24)*((24/V48)^(2/3)) -> 24.372075 | Y48: =X48*V48 -> 97.488301 | Z48: =Y48-Y47 -> 8.9143014 | AA48: =(Z48*100)/$Z$57 -> 6.3400749 | AB48: =AA50 -> 4.6799735 | AC48: =(AB48*$AC$41)/100 -> 8.2904794 | AF48: 4 | AG48: 3 4 | AH48: =($AM$41/24)*((24/AF48)^(2/3)) -> 26.737769 | AI48: =AH48*AF48 -> 106.95107 | AJ48: =AI48-AI47 -> 9.7795746 | AK48: =(AJ48*100)/$AJ$57 -> 6.3400749 | AL48: =AK50 -> 4.6799735 | AM48: =(AL48*$AM$41)/100 -> 9.0952009
...
