Workbook

Sheet Data
A1: Jarak Stasiun Kalbar-Pontianak kota: | F1: 14.2 | O1: Jarak Stasiun Pontianak kota-Kalbar | T1: 14.2 | AQ1: Jarak Stasiun Supadio-Pontianak kota: | AV1: 25 | AW1: km | BE1: Jarak Stasiun Supadio-Kalbar | BI1: 37.6
A2: Jarak Stasiun Kalbar-maritim pontianak: | F2: 20.3 | O2: Jarak Stasiun zPontianak kota- maritim pontianak | T2: 7.9 | AQ2: Jarak Stasiun Supadio-maritim pontianak: | AV2: 17.3 | AW2: km
O3: Jarak Stasiun Pontianak kota-Supadio | T3: 25
A5: Klim. Kalimantan Barat | O5: ARR Pontianak Kota | AC5: Meteorologi maritim Pontianak | AQ5: Meteorologi Supadio (2 stasiun) | BE5: Meteorologi Supadio (3 stasiun)
A7: Tahun 2013 | O7: Tahun 2013 | AC7: Tahun 2013 | AQ7: Tahun 2013 | BE7: Tahun 2013
B8: Bulan | P8: Bulan | AD8: Bulan | AR8: Bulan | BF8: Bulan
B9: Jan | C9: Feb | D9: Mar | E9: Apr | F9: Mei | G9: Jun | H9: Jul | I9: Agt | J9: Sept | K9: Okt | L9: Nov | M9: Des | P9: Jan | Q9: Feb | R9: Mar | S9: Apr | T9: Mei | U9: Jun | V9: Jul | W9: Agt | X9: Sept | Y9: Okt | Z9: Nov | AA9: Des | AD9: Jan | AE9: Feb | AF9: Mar | AG9: Apr | AH9: Mei | AI9: Jun | AJ9: Jul | AK9: Agt | AL9: Sept | AM9: Okt | AN9: Nov | AO9: Des | AR9: Jan | AS9: Feb | AT9: Mar | AU9: Apr | AV9: Mei | AW9: Jun | AX9: Jul | AY9: Agt | AZ9: Sept | BA9: Okt | BB9: Nov | BC9: Des | BF9: Jan | BG9: Feb | BH9: Mar | BI9: Apr | BJ9: Mei | BK9: Jun | BL9: Jul | BM9: Agt | BN9: Sept | BO9: Okt | BP9: Nov | BQ9: Des
A10: 1 | B10: =IF('Data 2'!B10<0.1,0,'Data 2'!B10) -> 32.901129 | C10: =IF('Data 2'!C10<0.1,0,'Data 2'!C10) -> 3.4826129 | D10: =IF('Data 2'!D10<0.1,0,'Data 2'!D10) -> 0 | E10: =IF('Data 2'!E10<0.1,0,'Data 2'!E10) -> 3.7741613 | F10: =IF('Data 2'!F10<0.1,0,'Data 2'!F10) -> 8.7617258 | G10: =IF('Data 2'!G10<0.1,0,'Data 2'!G10) -> 0 | H10: =IF('Data 2'!H10<0.1,0,'Data 2'!H10) -> 22.86221 | I10: =IF('Data 2'!I10<0.1,0,'Data 2'!I10) -> 1.3429032 | ... M10: =IF('Data 2'!M10<0.1,0,'Data 2'!M10) -> 18.127581 | O10: 1 | P10: ='Stasiun Pontianak Kota'!Q52 -> 49 | Q10: ='Stasiun Pontianak Kota'!R52 -> 0 | R10: ='Stasiun Pontianak Kota'!S52 -> 0 | S10: ='Stasiun Pontianak Kota'!T52 -> 2 | T10: ='Stasiun Pontianak Kota'!U52 -> 13 | U10: ='Stasiun Pontianak Kota'!V52 -> 0 | V10: ='Stasiun Pontianak Kota'!W52 -> 34 | W10: ='Stasiun Pontianak Kota'!X52 -> 2 | ... AA10: ='Stasiun Pontianak Kota'!AB52 -> 4 | AC10: 1 | AD10: ='Sta. Meteorologi pnk'!B8 -> 0 | AE10: ='Sta. Meteorologi pnk'!C8 -> 10.6 | AF10: ='Sta. Meteorologi pnk'!D8 -> 0 | AG10: ='Sta. Meteorologi pnk'!E8 -> 7.4 | AH10: ='Sta. Meteorologi pnk'!F8 -> 0.1 | AI10: ='Sta. Meteorologi pnk'!G8 -> 0.3 | AJ10: ='Sta. Meteorologi pnk'!H8 -> 0.1 | AK10: ='Sta. Meteorologi pnk'!I8 -> 0 | ... AO10: ='Sta. Meteorologi pnk'!M8 -> 47 | AQ10: 1 | AR10: =((P10/($AV$1^2))+(AD10/($AV$2^2)))/((1/($AV$1^2))+(1/($AV$2^2))) -> 15.86646 | AS10: =((Q10/($AV$1^2))+(AE10/($AV$2^2)))/((1/($AV$1^2))+(1/($AV$2^2))) -> 7.1676638 | AT10: =((R10/($AV$1^2))+(AF10/($AV$2^2)))/((1/($AV$1^2))+(1/($AV$2^2))) -> 0 | AU10: =((S10/($AV$1^2))+(AG10/($AV$2^2)))/((1/($AV$1^2))+(1/($AV$2^2))) -> 5.6514514 | AV10: =((T10/($AV$1^2))+(AH10/($AV$2^2)))/((1/($AV$1^2))+(1/($AV$2^2))) -> 4.2770884 | AW10: =((U10/($AV$1^2))+(AI10/($AV$2^2)))/((1/($AV$1^2))+(1/($AV$2^2))) -> 0.20285841 | AX10: =((V10/($AV$1^2))+(AJ10/($AV$2^2)))/((1/($AV$1^2))+(1/($AV$2^2))) -> 11.077 | AY10: =((W10/($AV$1^2))+(AK10/($AV$2^2)))/((1/($AV$1^2))+(1/($AV$2^2))) -> 0.6476106 | ... BC10: =((AA10/($AV$1^2))+(AO10/($AV$2^2)))/((1/($AV$1^2))+(1/($AV$2^2))) -> 33.076372 | BE10: 1 | BF10: =((B10/($BI$1^2))+(P10/($AV$1^2))+(AD10/($AV$2^2)))/((1/($BI$1^2))+(1/($AV$1^2))+(1/($AV$2^2))) -> 17.999599 | BG10: =((C10/($BI$1^2))+(Q10/($AV$1^2))+(AE10/($AV$2^2)))/((1/($BI$1^2))+(1/($AV$1^2))+(1/($AV$2^2))) -> 6.7062093 | BH10: =((D10/($BI$1^2))+(R10/($AV$1^2))+(AF10/($AV$2^2)))/((1/($BI$1^2))+(1/($AV$1^2))+(1/($AV$2^2))) -> 0 | BI10: =((E10/($BI$1^2))+(S10/($AV$1^2))+(AG10/($AV$2^2)))/((1/($BI$1^2))+(1/($AV$1^2))+(1/($AV$2^2))) -> 5.4163708 | BJ10: =((F10/($BI$1^2))+(T10/($AV$1^2))+(AH10/($AV$2^2)))/((1/($BI$1^2))+(1/($AV$1^2))+(1/($AV$2^2))) -> 4.8386699 | BK10: =((G10/($BI$1^2))+(U10/($AV$1^2))+(AI10/($AV$2^2)))/((1/($BI$1^2))+(1/($AV$1^2))+(1/($AV$2^2))) -> 0.17745579 | BL10: =((H10/($BI$1^2))+(V10/($AV$1^2))+(AJ10/($AV$2^2)))/((1/($BI$1^2))+(1/($AV$1^2))+(1/($AV$2^2))) -> 12.552784 | BM10: =((I10/($BI$1^2))+(W10/($AV$1^2))+(AK10/($AV$2^2)))/((1/($BI$1^2))+(1/($AV$1^2))+(1/($AV$2^2))) -> 0.7346775 | ... BQ10: =((M10/($BI$1^2))+(AA10/($AV$1^2))+(AO10/($AV$2^2)))/((1/($BI$1^2))+(1/($AV$1^2))+(1/($AV$2^2))) -> 31.204434
A11: 2 | B11: =IF('Data 2'!B11<0.1,0,'Data 2'!B11) -> 0.39425806 | C11: =IF('Data 2'!C11<0.1,0,'Data 2'!C11) -> 0.65709677 | D11: =IF('Data 2'!D11<0.1,0,'Data 2'!D11) -> 0 | E11: =IF('Data 2'!E11<0.1,0,'Data 2'!E11) -> 0 | F11: =IF('Data 2'!F11<0.1,0,'Data 2'!F11) -> 3.1129194 | G11: =IF('Data 2'!G11<0.1,0,'Data 2'!G11) -> 0 | H11: =IF('Data 2'!H11<0.1,0,'Data 2'!H11) -> 0.4271129 | I11: =IF('Data 2'!I11<0.1,0,'Data 2'!I11) -> 0 | ... M11: =IF('Data 2'!M11<0.1,0,'Data 2'!M11) -> 29.975129 | O11: 2 | P11: ='Stasiun Pontianak Kota'!Q53 -> 0 | Q11: ='Stasiun Pontianak Kota'!R53 -> 0 | R11: ='Stasiun Pontianak Kota'!S53 -> 0 | S11: ='Stasiun Pontianak Kota'!T53 -> 0 | T11: ='Stasiun Pontianak Kota'!U53 -> 4 | U11: ='Stasiun Pontianak Kota'!V53 -> 0 | V11: ='Stasiun Pontianak Kota'!W53 -> 0 | W11: ='Stasiun Pontianak Kota'!X53 -> 0 | ... AA11: ='Stasiun Pontianak Kota'!AB53 -> 42 | AC11: 2 | AD11: ='Sta. Meteorologi pnk'!B9 -> 1.2 | AE11: ='Sta. Meteorologi pnk'!C9 -> 2 | AF11: ='Sta. Meteorologi pnk'!D9 -> 0 | AG11: ='Sta. Meteorologi pnk'!E9 -> 0 | AH11: ='Sta. Meteorologi pnk'!F9 -> 1.3 | AI11: ='Sta. Meteorologi pnk'!G9 -> 0 | AJ11: ='Sta. Meteorologi pnk'!H9 -> 1.3 | AK11: ='Sta. Meteorologi pnk'!I9 -> 0 | ... AO11: ='Sta. Meteorologi pnk'!M9 -> 5.4 | AQ11: 2 | AR11: =((P11/($AV$1^2))+(AD11/($AV$2^2)))/((1/($AV$1^2))+(1/($AV$2^2))) -> 0.81143364 | AS11: =((Q11/($AV$1^2))+(AE11/($AV$2^2)))/((1/($AV$1^2))+(1/($AV$2^2))) -> 1.3523894 | AT11: =((R11/($AV$1^2))+(AF11/($AV$2^2)))/((1/($AV$1^2))+(1/($AV$2^2))) -> 0 | AU11: =((S11/($AV$1^2))+(AG11/($AV$2^2)))/((1/($AV$1^2))+(1/($AV$2^2))) -> 0 | AV11: =((T11/($AV$1^2))+(AH11/($AV$2^2)))/((1/($AV$1^2))+(1/($AV$2^2))) -> 2.1742743 | AW11: =((U11/($AV$1^2))+(AI11/($AV$2^2)))/((1/($AV$1^2))+(1/($AV$2^2))) -> 0 | AX11: =((V11/($AV$1^2))+(AJ11/($AV$2^2)))/((1/($AV$1^2))+(1/($AV$2^2))) -> 0.87905311 | AY11: =((W11/($AV$1^2))+(AK11/($AV$2^2)))/((1/($AV$1^2))+(1/($AV$2^2))) -> 0 | ... BC11: =((AA11/($AV$1^2))+(AO11/($AV$2^2)))/((1/($AV$1^2))+(1/($AV$2^2))) -> 17.251274 | BE11: 2 | BF11: =((B11/($BI$1^2))+(P11/($AV$1^2))+(AD11/($AV$2^2)))/((1/($BI$1^2))+(1/($AV$1^2))+(1/($AV$2^2))) -> 0.7591935 | BG11: =((C11/($BI$1^2))+(Q11/($AV$1^2))+(AE11/($AV$2^2)))/((1/($BI$1^2))+(1/($AV$1^2))+(1/($AV$2^2))) -> 1.2653225 | BH11: =((D11/($BI$1^2))+(R11/($AV$1^2))+(AF11/($AV$2^2)))/((1/($BI$1^2))+(1/($AV$1^2))+(1/($AV$2^2))) -> 0 | BI11: =((E11/($BI$1^2))+(S11/($AV$1^2))+(AG11/($AV$2^2)))/((1/($BI$1^2))+(1/($AV$1^2))+(1/($AV$2^2))) -> 0 | BJ11: =((F11/($BI$1^2))+(T11/($AV$1^2))+(AH11/($AV$2^2)))/((1/($BI$1^2))+(1/($AV$1^2))+(1/($AV$2^2))) -> 2.2918146 | BK11: =((G11/($BI$1^2))+(U11/($AV$1^2))+(AI11/($AV$2^2)))/((1/($BI$1^2))+(1/($AV$1^2))+(1/($AV$2^2))) -> 0 | BL11: =((H11/($BI$1^2))+(V11/($AV$1^2))+(AJ11/($AV$2^2)))/((1/($BI$1^2))+(1/($AV$1^2))+(1/($AV$2^2))) -> 0.82245963 | BM11: =((I11/($BI$1^2))+(W11/($AV$1^2))+(AK11/($AV$2^2)))/((1/($BI$1^2))+(1/($AV$1^2))+(1/($AV$2^2))) -> 0 | ... BQ11: =((M11/($BI$1^2))+(AA11/($AV$1^2))+(AO11/($AV$2^2)))/((1/($BI$1^2))+(1/($AV$1^2))+(1/($AV$2^2))) -> 18.844598
A12: 3 | B12: =IF('Data 2'!B12<0.1,0,'Data 2'!B12) -> 2.0472097 | C12: =IF('Data 2'!C12<0.1,0,'Data 2'!C12) -> 6.5381129 | D12: =IF('Data 2'!D12<0.1,0,'Data 2'!D12) -> 0 | E12: =IF('Data 2'!E12<0.1,0,'Data 2'!E12) -> 0 | F12: =IF('Data 2'!F12<0.1,0,'Data 2'!F12) -> 22.012742 | G12: =IF('Data 2'!G12<0.1,0,'Data 2'!G12) -> 0 | H12: =IF('Data 2'!H12<0.1,0,'Data 2'!H12) -> 8.2216936 | I12: =IF('Data 2'!I12<0.1,0,'Data 2'!I12) -> 0 | ... M12: =IF('Data 2'!M12<0.1,0,'Data 2'!M12) -> 8.8255161 | O12: 3 | P12: ='Stasiun Pontianak Kota'!Q54 -> 3 | Q12: ='Stasiun Pontianak Kota'!R54 -> 0 | R12: ='Stasiun Pontianak Kota'!S54 -> 0 | S12: ='Stasiun Pontianak Kota'!T54 -> 0 | T12: ='Stasiun Pontianak Kota'!U54 -> 0 | U12: ='Stasiun Pontianak Kota'!V54 -> 0 | V12: ='Stasiun Pontianak Kota'!W54 -> 12 | W12: ='Stasiun Pontianak Kota'!X54 -> 0 | ... AA12: ='Stasiun Pontianak Kota'!AB54 -> 6 | AC12: 3 | AD12: ='Sta. Meteorologi pnk'!B10 -> 0.1 | AE12: ='Sta. Meteorologi pnk'!C10 -> 19.9 | AF12: ='Sta. Meteorologi pnk'!D10 -> 0 | AG12: ='Sta. Meteorologi pnk'!E10 -> 0 | AH12: ='Sta. Meteorologi pnk'!F10 -> 67 | AI12: ='Sta. Meteorologi pnk'!G10 -> 0 | AJ12: ='Sta. Meteorologi pnk'!H10 -> 0.5 | AK12: ='Sta. Meteorologi pnk'!I10 -> 0 | ... AO12: ='Sta. Meteorologi pnk'!M10 -> 14.6 | AQ12: 3 | AR12: =((P12/($AV$1^2))+(AD12/($AV$2^2)))/((1/($AV$1^2))+(1/($AV$2^2))) -> 1.0390354 | AS12: =((Q12/($AV$1^2))+(AE12/($AV$2^2)))/((1/($AV$1^2))+(1/($AV$2^2))) -> 13.456275 | AT12: =((R12/($AV$1^2))+(AF12/($AV$2^2)))/((1/($AV$1^2))+(1/($AV$2^2))) -> 0 | AU12: =((S12/($AV$1^2))+(AG12/($AV$2^2)))/((1/($AV$1^2))+(1/($AV$2^2))) -> 0 | AV12: =((T12/($AV$1^2))+(AH12/($AV$2^2)))/((1/($AV$1^2))+(1/($AV$2^2))) -> 45.305045 | AW12: =((U12/($AV$1^2))+(AI12/($AV$2^2)))/((1/($AV$1^2))+(1/($AV$2^2))) -> 0 | AX12: =((V12/($AV$1^2))+(AJ12/($AV$2^2)))/((1/($AV$1^2))+(1/($AV$2^2))) -> 4.2237609 | AY12: =((W12/($AV$1^2))+(AK12/($AV$2^2)))/((1/($AV$1^2))+(1/($AV$2^2))) -> 0 | ... BC12: =((AA12/($AV$1^2))+(AO12/($AV$2^2)))/((1/($AV$1^2))+(1/($AV$2^2))) -> 11.815274 | BE12: 3 | BF12: =((B12/($BI$1^2))+(P12/($AV$1^2))+(AD12/($AV$2^2)))/((1/($BI$1^2))+(1/($AV$1^2))+(1/($AV$2^2))) -> 1.1652824 | BG12: =((C12/($BI$1^2))+(Q12/($AV$1^2))+(AE12/($AV$2^2)))/((1/($BI$1^2))+(1/($AV$1^2))+(1/($AV$2^2))) -> 12.589959 | BH12: =((D12/($BI$1^2))+(R12/($AV$1^2))+(AF12/($AV$2^2)))/((1/($BI$1^2))+(1/($AV$1^2))+(1/($AV$2^2))) -> 0 | BI12: =((E12/($BI$1^2))+(S12/($AV$1^2))+(AG12/($AV$2^2)))/((1/($BI$1^2))+(1/($AV$1^2))+(1/($AV$2^2))) -> 0 | BJ12: =((F12/($BI$1^2))+(T12/($AV$1^2))+(AH12/($AV$2^2)))/((1/($BI$1^2))+(1/($AV$1^2))+(1/($AV$2^2))) -> 42.388304 | BK12: =((G12/($BI$1^2))+(U12/($AV$1^2))+(AI12/($AV$2^2)))/((1/($BI$1^2))+(1/($AV$1^2))+(1/($AV$2^2))) -> 0 | BL12: =((H12/($BI$1^2))+(V12/($AV$1^2))+(AJ12/($AV$2^2)))/((1/($BI$1^2))+(1/($AV$1^2))+(1/($AV$2^2))) -> 4.7243956 | BM12: =((I12/($BI$1^2))+(W12/($AV$1^2))+(AK12/($AV$2^2)))/((1/($BI$1^2))+(1/($AV$1^2))+(1/($AV$2^2))) -> 0 | ... BQ12: =((M12/($BI$1^2))+(AA12/($AV$1^2))+(AO12/($AV$2^2)))/((1/($BI$1^2))+(1/($AV$1^2))+(1/($AV$2^2))) -> 11.440887
A13: 4 | B13: =IF('Data 2'!B13<0.1,0,'Data 2'!B13) -> 0.16427419 | C13: =IF('Data 2'!C13<0.1,0,'Data 2'!C13) -> 26.186613 | D13: =IF('Data 2'!D13<0.1,0,'Data 2'!D13) -> 0.13141935 | E13: =IF('Data 2'!E13<0.1,0,'Data 2'!E13) -> 2.1027097 | F13: =IF('Data 2'!F13<0.1,0,'Data 2'!F13) -> 58.711984 | G13: =IF('Data 2'!G13<0.1,0,'Data 2'!G13) -> 0.19712903 | H13: =IF('Data 2'!H13<0.1,0,'Data 2'!H13) -> 4.7001613 | I13: =IF('Data 2'!I13<0.1,0,'Data 2'!I13) -> 14.653258 | ... M13: =IF('Data 2'!M13<0.1,0,'Data 2'!M13) -> 4.4743226 | O13: 4 | P13: ='Stasiun Pontianak Kota'!Q55 -> 0 | Q13: ='Stasiun Pontianak Kota'!R55 -> 39 | R13: ='Stasiun Pontianak Kota'!S55 -> 0 | S13: ='Stasiun Pontianak Kota'!T55 -> 0 | T13: ='Stasiun Pontianak Kota'!U55 -> 87 | U13: ='Stasiun Pontianak Kota'!V55 -> 0 | V13: ='Stasiun Pontianak Kota'!W55 -> 7 | W13: ='Stasiun Pontianak Kota'!X55 -> 0 | ... AA13: ='Stasiun Pontianak Kota'!AB55 -> 5 | AC13: 4 | AD13: ='Sta. Meteorologi pnk'!B11 -> 0.5 | AE13: ='Sta. Meteorologi pnk'!C11 -> 0 | AF13: ='Sta. Meteorologi pnk'!D11 -> 0.4 | AG13: ='Sta. Meteorologi pnk'!E11 -> 6.4 | AH13: ='Sta. Meteorologi pnk'!F11 -> 0.9 | AI13: ='Sta. Meteorologi pnk'!G11 -> 0.6 | AJ13: ='Sta. Meteorologi pnk'!H11 -> 0 | AK13: ='Sta. Meteorologi pnk'!I11 -> 44.6 | ... AO13: ='Sta. Meteorologi pnk'!M11 -> 3.4 | AQ13: 4 | AR13: =((P13/($AV$1^2))+(AD13/($AV$2^2)))/((1/($AV$1^2))+(1/($AV$2^2))) -> 0.33809735 | AS13: =((Q13/($AV$1^2))+(AE13/($AV$2^2)))/((1/($AV$1^2))+(1/($AV$2^2))) -> 12.628407 | AT13: =((R13/($AV$1^2))+(AF13/($AV$2^2)))/((1/($AV$1^2))+(1/($AV$2^2))) -> 0.27047788 | AU13: =((S13/($AV$1^2))+(AG13/($AV$2^2)))/((1/($AV$1^2))+(1/($AV$2^2))) -> 4.3276461 | AV13: =((T13/($AV$1^2))+(AH13/($AV$2^2)))/((1/($AV$1^2))+(1/($AV$2^2))) -> 28.779636 | AW13: =((U13/($AV$1^2))+(AI13/($AV$2^2)))/((1/($AV$1^2))+(1/($AV$2^2))) -> 0.40571682 | AX13: =((V13/($AV$1^2))+(AJ13/($AV$2^2)))/((1/($AV$1^2))+(1/($AV$2^2))) -> 2.2666371 | AY13: =((W13/($AV$1^2))+(AK13/($AV$2^2)))/((1/($AV$1^2))+(1/($AV$2^2))) -> 30.158284 | ... BC13: =((AA13/($AV$1^2))+(AO13/($AV$2^2)))/((1/($AV$1^2))+(1/($AV$2^2))) -> 3.9180885 | BE13: 4 | BF13: =((B13/($BI$1^2))+(P13/($AV$1^2))+(AD13/($AV$2^2)))/((1/($BI$1^2))+(1/($AV$1^2))+(1/($AV$2^2))) -> 0.31633063 | BG13: =((C13/($BI$1^2))+(Q13/($AV$1^2))+(AE13/($AV$2^2)))/((1/($BI$1^2))+(1/($AV$1^2))+(1/($AV$2^2))) -> 14.326211 | BH13: =((D13/($BI$1^2))+(R13/($AV$1^2))+(AF13/($AV$2^2)))/((1/($BI$1^2))+(1/($AV$1^2))+(1/($AV$2^2))) -> 0.2530645 | BI13: =((E13/($BI$1^2))+(S13/($AV$1^2))+(AG13/($AV$2^2)))/((1/($BI$1^2))+(1/($AV$1^2))+(1/($AV$2^2))) -> 4.049032 | BJ13: =((F13/($BI$1^2))+(T13/($AV$1^2))+(AH13/($AV$2^2)))/((1/($BI$1^2))+(1/($AV$1^2))+(1/($AV$2^2))) -> 32.527866 | BK13: =((G13/($BI$1^2))+(U13/($AV$1^2))+(AI13/($AV$2^2)))/((1/($BI$1^2))+(1/($AV$1^2))+(1/($AV$2^2))) -> 0.37959675 | BL13: =((H13/($BI$1^2))+(V13/($AV$1^2))+(AJ13/($AV$2^2)))/((1/($BI$1^2))+(1/($AV$1^2))+(1/($AV$2^2))) -> 2.5713712 | BM13: =((I13/($BI$1^2))+(W13/($AV$1^2))+(AK13/($AV$2^2)))/((1/($BI$1^2))+(1/($AV$1^2))+(1/($AV$2^2))) -> 28.216692 | ... BQ13: =((M13/($BI$1^2))+(AA13/($AV$1^2))+(AO13/($AV$2^2)))/((1/($BI$1^2))+(1/($AV$1^2))+(1/($AV$2^2))) -> 3.987742
A14: 5 | B14: =IF('Data 2'!B14<0.1,0,'Data 2'!B14) -> 0 | C14: =IF('Data 2'!C14<0.1,0,'Data 2'!C14) -> 36.304596 | D14: =IF('Data 2'!D14<0.1,0,'Data 2'!D14) -> 16.033161 | E14: =IF('Data 2'!E14<0.1,0,'Data 2'!E14) -> 6.7145162 | F14: =IF('Data 2'!F14<0.1,0,'Data 2'!F14) -> 7.486758 | G14: =IF('Data 2'!G14<0.1,0,'Data 2'!G14) -> 24.607968 | H14: =IF('Data 2'!H14<0.1,0,'Data 2'!H14) -> 0 | I14: =IF('Data 2'!I14<0.1,0,'Data 2'!I14) -> 18.129194 | ... M14: =IF('Data 2'!M14<0.1,0,'Data 2'!M14) -> 5.6015968 | O14: 5 | P14: ='Stasiun Pontianak Kota'!Q56 -> 0 | Q14: ='Stasiun Pontianak Kota'!R56 -> 0 | R14: ='Stasiun Pontianak Kota'!S56 -> 0 | S14: ='Stasiun Pontianak Kota'!T56 -> 10 | T14: ='Stasiun Pontianak Kota'!U56 -> 2 | U14: ='Stasiun Pontianak Kota'!V56 -> 16 | V14: ='Stasiun Pontianak Kota'!W56 -> 0 | W14: ='Stasiun Pontianak Kota'!X56 -> 27 | ... AA14: ='Stasiun Pontianak Kota'!AB56 -> 8 | AC14: 5 | AD14: ='Sta. Meteorologi pnk'!B12 -> 0 | AE14: ='Sta. Meteorologi pnk'!C12 -> 110.5 | AF14: ='Sta. Meteorologi pnk'!D12 -> 48.8 | AG14: ='Sta. Meteorologi pnk'!E12 -> 0 | AH14: ='Sta. Meteorologi pnk'!F12 -> 18.7 | AI14: ='Sta. Meteorologi pnk'!G12 -> 42.2 | AJ14: ='Sta. Meteorologi pnk'!H12 -> 0 | AK14: ='Sta. Meteorologi pnk'!I12 -> 0 | ... AO14: ='Sta. Meteorologi pnk'!M12 -> 0.7 | AQ14: 5 | AR14: =((P14/($AV$1^2))+(AD14/($AV$2^2)))/((1/($AV$1^2))+(1/($AV$2^2))) -> 0 | AS14: =((Q14/($AV$1^2))+(AE14/($AV$2^2)))/((1/($AV$1^2))+(1/($AV$2^2))) -> 74.719514 | AT14: =((R14/($AV$1^2))+(AF14/($AV$2^2)))/((1/($AV$1^2))+(1/($AV$2^2))) -> 32.998301 | AU14: =((S14/($AV$1^2))+(AG14/($AV$2^2)))/((1/($AV$1^2))+(1/($AV$2^2))) -> 3.238053 | AV14: =((T14/($AV$1^2))+(AH14/($AV$2^2)))/((1/($AV$1^2))+(1/($AV$2^2))) -> 13.292452 | AW14: =((U14/($AV$1^2))+(AI14/($AV$2^2)))/((1/($AV$1^2))+(1/($AV$2^2))) -> 33.716301 | AX14: =((V14/($AV$1^2))+(AJ14/($AV$2^2)))/((1/($AV$1^2))+(1/($AV$2^2))) -> 0 | AY14: =((W14/($AV$1^2))+(AK14/($AV$2^2)))/((1/($AV$1^2))+(1/($AV$2^2))) -> 8.7427431 | ... BC14: =((AA14/($AV$1^2))+(AO14/($AV$2^2)))/((1/($AV$1^2))+(1/($AV$2^2))) -> 3.0637787 | BE14: 5 | BF14: =((B14/($BI$1^2))+(P14/($AV$1^2))+(AD14/($AV$2^2)))/((1/($BI$1^2))+(1/($AV$1^2))+(1/($AV$2^2))) -> 0 | BG14: =((C14/($BI$1^2))+(Q14/($AV$1^2))+(AE14/($AV$2^2)))/((1/($BI$1^2))+(1/($AV$1^2))+(1/($AV$2^2))) -> 69.909068 | BH14: =((D14/($BI$1^2))+(R14/($AV$1^2))+(AF14/($AV$2^2)))/((1/($BI$1^2))+(1/($AV$1^2))+(1/($AV$2^2))) -> 30.873869 | BI14: =((E14/($BI$1^2))+(S14/($AV$1^2))+(AG14/($AV$2^2)))/((1/($BI$1^2))+(1/($AV$1^2))+(1/($AV$2^2))) -> 3.6733875 | BJ14: =((F14/($BI$1^2))+(T14/($AV$1^2))+(AH14/($AV$2^2)))/((1/($BI$1^2))+(1/($AV$1^2))+(1/($AV$2^2))) -> 12.565443 | BK14: =((G14/($BI$1^2))+(U14/($AV$1^2))+(AI14/($AV$2^2)))/((1/($BI$1^2))+(1/($AV$1^2))+(1/($AV$2^2))) -> 32.575725 | BL14: =((H14/($BI$1^2))+(V14/($AV$1^2))+(AJ14/($AV$2^2)))/((1/($BI$1^2))+(1/($AV$1^2))+(1/($AV$2^2))) -> 0 | BM14: =((I14/($BI$1^2))+(W14/($AV$1^2))+(AK14/($AV$2^2)))/((1/($BI$1^2))+(1/($AV$1^2))+(1/($AV$2^2))) -> 9.9181462 | ... BQ14: =((M14/($BI$1^2))+(AA14/($AV$1^2))+(AO14/($AV$2^2)))/((1/($BI$1^2))+(1/($AV$1^2))+(1/($AV$2^2))) -> 3.3815729
A15: 6 | B15: =IF('Data 2'!B15<0.1,0,'Data 2'!B15) -> 0 | C15: =IF('Data 2'!C15<0.1,0,'Data 2'!C15) -> 51.252323 | D15: =IF('Data 2'!D15<0.1,0,'Data 2'!D15) -> 20.815 | E15: =IF('Data 2'!E15<0.1,0,'Data 2'!E15) -> 33.183387 | F15: =IF('Data 2'!F15<0.1,0,'Data 2'!F15) -> 34.285484 | G15: =IF('Data 2'!G15<0.1,0,'Data 2'!G15) -> 12.086129 | H15: =IF('Data 2'!H15<0.1,0,'Data 2'!H15) -> 42.046903 | I15: =IF('Data 2'!I15<0.1,0,'Data 2'!I15) -> 0 | ... M15: =IF('Data 2'!M15<0.1,0,'Data 2'!M15) -> 1 | O15: 6 | P15: ='Stasiun Pontianak Kota'!Q57 -> 0 | Q15: ='Stasiun Pontianak Kota'!R57 -> 64 | R15: ='Stasiun Pontianak Kota'!S57 -> 31 | S15: ='Stasiun Pontianak Kota'!T57 -> 0 | T15: ='Stasiun Pontianak Kota'!U57 -> 31 | U15: ='Stasiun Pontianak Kota'!V57 -> 18 | V15: ='Stasiun Pontianak Kota'!W57 -> 59 | W15: ='Stasiun Pontianak Kota'!X57 -> 0 | ... AA15: ='Stasiun Pontianak Kota'!AB57 -> 1 | AC15: 6 | AD15: ='Sta. Meteorologi pnk'!B13 -> 0 | AE15: ='Sta. Meteorologi pnk'!C13 -> 25.2 | AF15: ='Sta. Meteorologi pnk'!D13 -> 0 | AG15: ='Sta. Meteorologi pnk'!E13 -> 101 | AH15: ='Sta. Meteorologi pnk'!F13 -> 41 | AI15: ='Sta. Meteorologi pnk'!G13 -> 0 | AJ15: ='Sta. Meteorologi pnk'!H13 -> 7.4 | AK15: ='Sta. Meteorologi pnk'!I13 -> 0 | ... AO15: ='Sta. Meteorologi pnk'!M13 -> 1 | AQ15: 6 | AR15: =((P15/($AV$1^2))+(AD15/($AV$2^2)))/((1/($AV$1^2))+(1/($AV$2^2))) -> 0 | AS15: =((Q15/($AV$1^2))+(AE15/($AV$2^2)))/((1/($AV$1^2))+(1/($AV$2^2))) -> 37.763646 | AT15: =((R15/($AV$1^2))+(AF15/($AV$2^2)))/((1/($AV$1^2))+(1/($AV$2^2))) -> 10.037964 | AU15: =((S15/($AV$1^2))+(AG15/($AV$2^2)))/((1/($AV$1^2))+(1/($AV$2^2))) -> 68.295665 | AV15: =((T15/($AV$1^2))+(AH15/($AV$2^2)))/((1/($AV$1^2))+(1/($AV$2^2))) -> 37.761947 | AW15: =((U15/($AV$1^2))+(AI15/($AV$2^2)))/((1/($AV$1^2))+(1/($AV$2^2))) -> 5.8284954 | AX15: =((V15/($AV$1^2))+(AJ15/($AV$2^2)))/((1/($AV$1^2))+(1/($AV$2^2))) -> 24.108353 | AY15: =((W15/($AV$1^2))+(AK15/($AV$2^2)))/((1/($AV$1^2))+(1/($AV$2^2))) -> 0 | ... BC15: =((AA15/($AV$1^2))+(AO15/($AV$2^2)))/((1/($AV$1^2))+(1/($AV$2^2))) -> 1 | BE15: 6 | BF15: =((B15/($BI$1^2))+(P15/($AV$1^2))+(AD15/($AV$2^2)))/((1/($BI$1^2))+(1/($AV$1^2))+(1/($AV$2^2))) -> 0 | BG15: =((C15/($BI$1^2))+(Q15/($AV$1^2))+(AE15/($AV$2^2)))/((1/($BI$1^2))+(1/($AV$1^2))+(1/($AV$2^2))) -> 39.452743 | BH15: =((D15/($BI$1^2))+(R15/($AV$1^2))+(AF15/($AV$2^2)))/((1/($BI$1^2))+(1/($AV$1^2))+(1/($AV$2^2))) -> 11.387501 | BI15: =((E15/($BI$1^2))+(S15/($AV$1^2))+(AG15/($AV$2^2)))/((1/($BI$1^2))+(1/($AV$1^2))+(1/($AV$2^2))) -> 63.898786 | BJ15: =((F15/($BI$1^2))+(T15/($AV$1^2))+(AH15/($AV$2^2)))/((1/($BI$1^2))+(1/($AV$1^2))+(1/($AV$2^2))) -> 37.326613 | BK15: =((G15/($BI$1^2))+(U15/($AV$1^2))+(AI15/($AV$2^2)))/((1/($BI$1^2))+(1/($AV$1^2))+(1/($AV$2^2))) -> 6.6120975 | BL15: =((H15/($BI$1^2))+(V15/($AV$1^2))+(AJ15/($AV$2^2)))/((1/($BI$1^2))+(1/($AV$1^2))+(1/($AV$2^2))) -> 26.354679 | BM15: =((I15/($BI$1^2))+(W15/($AV$1^2))+(AK15/($AV$2^2)))/((1/($BI$1^2))+(1/($AV$1^2))+(1/($AV$2^2))) -> 0 | ... BQ15: =((M15/($BI$1^2))+(AA15/($AV$1^2))+(AO15/($AV$2^2)))/((1/($BI$1^2))+(1/($AV$1^2))+(1/($AV$2^2))) -> 1
A16: 7 | B16: =IF('Data 2'!B16<0.1,0,'Data 2'!B16) -> 0 | C16: =IF('Data 2'!C16<0.1,0,'Data 2'!C16) -> 14.100484 | D16: =IF('Data 2'!D16<0.1,0,'Data 2'!D16) -> 0 | E16: =IF('Data 2'!E16<0.1,0,'Data 2'!E16) -> 70.229984 | F16: =IF('Data 2'!F16<0.1,0,'Data 2'!F16) -> 47.117065 | G16: =IF('Data 2'!G16<0.1,0,'Data 2'!G16) -> 0 | H16: =IF('Data 2'!H16<0.1,0,'Data 2'!H16) -> 0 | I16: =IF('Data 2'!I16<0.1,0,'Data 2'!I16) -> 2.6858065 | ... M16: =IF('Data 2'!M16<0.1,0,'Data 2'!M16) -> 15.883242 | O16: 7 | P16: ='Stasiun Pontianak Kota'!Q58 -> 0 | Q16: ='Stasiun Pontianak Kota'!R58 -> 21 | R16: ='Stasiun Pontianak Kota'!S58 -> 0 | S16: ='Stasiun Pontianak Kota'!T58 -> 70 | T16: ='Stasiun Pontianak Kota'!U58 -> 46 | U16: ='Stasiun Pontianak Kota'!V58 -> 0 | V16: ='Stasiun Pontianak Kota'!W58 -> 0 | W16: ='Stasiun Pontianak Kota'!X58 -> 4 | ... AA16: ='Stasiun Pontianak Kota'!AB58 -> 1 | AC16: 7 | AD16: ='Sta. Meteorologi pnk'!B14 -> 0 | AE16: ='Sta. Meteorologi pnk'!C14 -> 0 | AF16: ='Sta. Meteorologi pnk'!D14 -> 0 | AG16: ='Sta. Meteorologi pnk'!E14 -> 70.7 | AH16: ='Sta. Meteorologi pnk'!F14 -> 49.4 | AI16: ='Sta. Meteorologi pnk'!G14 -> 0 | AJ16: ='Sta. Meteorologi pnk'!H14 -> 0 | AK16: ='Sta. Meteorologi pnk'!I14 -> 0 | ... AO16: ='Sta. Meteorologi pnk'!M14 -> 46.3 | AQ16: 7 | AR16: =((P16/($AV$1^2))+(AD16/($AV$2^2)))/((1/($AV$1^2))+(1/($AV$2^2))) -> 0 | AS16: =((Q16/($AV$1^2))+(AE16/($AV$2^2)))/((1/($AV$1^2))+(1/($AV$2^2))) -> 6.7999113 | AT16: =((R16/($AV$1^2))+(AF16/($AV$2^2)))/((1/($AV$1^2))+(1/($AV$2^2))) -> 0 | AU16: =((S16/($AV$1^2))+(AG16/($AV$2^2)))/((1/($AV$1^2))+(1/($AV$2^2))) -> 70.473336 | AV16: =((T16/($AV$1^2))+(AH16/($AV$2^2)))/((1/($AV$1^2))+(1/($AV$2^2))) -> 48.299062 | AW16: =((U16/($AV$1^2))+(AI16/($AV$2^2)))/((1/($AV$1^2))+(1/($AV$2^2))) -> 0 | AX16: =((V16/($AV$1^2))+(AJ16/($AV$2^2)))/((1/($AV$1^2))+(1/($AV$2^2))) -> 0 | AY16: =((W16/($AV$1^2))+(AK16/($AV$2^2)))/((1/($AV$1^2))+(1/($AV$2^2))) -> 1.2952212 | ... BC16: =((AA16/($AV$1^2))+(AO16/($AV$2^2)))/((1/($AV$1^2))+(1/($AV$2^2))) -> 31.63162 | BE16: 7 | BF16: =((B16/($BI$1^2))+(P16/($AV$1^2))+(AD16/($AV$2^2)))/((1/($BI$1^2))+(1/($AV$1^2))+(1/($AV$2^2))) -> 0 | BG16: =((C16/($BI$1^2))+(Q16/($AV$1^2))+(AE16/($AV$2^2)))/((1/($BI$1^2))+(1/($AV$1^2))+(1/($AV$2^2))) -> 7.7141137 | BH16: =((D16/($BI$1^2))+(R16/($AV$1^2))+(AF16/($AV$2^2)))/((1/($BI$1^2))+(1/($AV$1^2))+(1/($AV$2^2))) -> 0 | BI16: =((E16/($BI$1^2))+(S16/($AV$1^2))+(AG16/($AV$2^2)))/((1/($BI$1^2))+(1/($AV$1^2))+(1/($AV$2^2))) -> 70.442863 | BJ16: =((F16/($BI$1^2))+(T16/($AV$1^2))+(AH16/($AV$2^2)))/((1/($BI$1^2))+(1/($AV$1^2))+(1/($AV$2^2))) -> 48.151048 | BK16: =((G16/($BI$1^2))+(U16/($AV$1^2))+(AI16/($AV$2^2)))/((1/($BI$1^2))+(1/($AV$1^2))+(1/($AV$2^2))) -> 0 | BL16: =((H16/($BI$1^2))+(V16/($AV$1^2))+(AJ16/($AV$2^2)))/((1/($BI$1^2))+(1/($AV$1^2))+(1/($AV$2^2))) -> 0 | BM16: =((I16/($BI$1^2))+(W16/($AV$1^2))+(AK16/($AV$2^2)))/((1/($BI$1^2))+(1/($AV$1^2))+(1/($AV$2^2))) -> 1.469355 | ... BQ16: =((M16/($BI$1^2))+(AA16/($AV$1^2))+(AO16/($AV$2^2)))/((1/($BI$1^2))+(1/($AV$1^2))+(1/($AV$2^2))) -> 29.659555
A17: 8 | B17: =IF('Data 2'!B17<0.1,0,'Data 2'!B17) -> 0 | C17: =IF('Data 2'!C17<0.1,0,'Data 2'!C17) -> 0 | D17: =IF('Data 2'!D17<0.1,0,'Data 2'!D17) -> 0 | E17: =IF('Data 2'!E17<0.1,0,'Data 2'!E17) -> 58.416291 | F17: =IF('Data 2'!F17<0.1,0,'Data 2'!F17) -> 75.202581 | G17: =IF('Data 2'!G17<0.1,0,'Data 2'!G17) -> 0 | H17: =IF('Data 2'!H17<0.1,0,'Data 2'!H17) -> 0 | I17: =IF('Data 2'!I17<0.1,0,'Data 2'!I17) -> 0 | ... M17: =IF('Data 2'!M17<0.1,0,'Data 2'!M17) -> 20.043065 | O17: 8 | P17: ='Stasiun Pontianak Kota'!Q59 -> 0 | Q17: ='Stasiun Pontianak Kota'!R59 -> 0 | R17: ='Stasiun Pontianak Kota'!S59 -> 0 | S17: ='Stasiun Pontianak Kota'!T59 -> 87 | T17: ='Stasiun Pontianak Kota'!U59 -> 112 | U17: ='Stasiun Pontianak Kota'!V59 -> 0 | V17: ='Stasiun Pontianak Kota'!W59 -> 0 | W17: ='Stasiun Pontianak Kota'!X59 -> 0 | ... AA17: ='Stasiun Pontianak Kota'!AB59 -> 23 | AC17: 8 | AD17: ='Sta. Meteorologi pnk'!B15 -> 0 | AE17: ='Sta. Meteorologi pnk'!C15 -> 0 | AF17: ='Sta. Meteorologi pnk'!D15 -> 0 | AG17: ='Sta. Meteorologi pnk'!E15 -> 0 | AH17: ='Sta. Meteorologi pnk'!F15 -> 0 | AI17: ='Sta. Meteorologi pnk'!G15 -> 0 | AJ17: ='Sta. Meteorologi pnk'!H15 -> 0.1 | AK17: ='Sta. Meteorologi pnk'!I15 -> 0 | ... AO17: ='Sta. Meteorologi pnk'!M15 -> 14 | AQ17: 8 | AR17: =((P17/($AV$1^2))+(AD17/($AV$2^2)))/((1/($AV$1^2))+(1/($AV$2^2))) -> 0 | AS17: =((Q17/($AV$1^2))+(AE17/($AV$2^2)))/((1/($AV$1^2))+(1/($AV$2^2))) -> 0 | AT17: =((R17/($AV$1^2))+(AF17/($AV$2^2)))/((1/($AV$1^2))+(1/($AV$2^2))) -> 0 | AU17: =((S17/($AV$1^2))+(AG17/($AV$2^2)))/((1/($AV$1^2))+(1/($AV$2^2))) -> 28.171061 | AV17: =((T17/($AV$1^2))+(AH17/($AV$2^2)))/((1/($AV$1^2))+(1/($AV$2^2))) -> 36.266194 | AW17: =((U17/($AV$1^2))+(AI17/($AV$2^2)))/((1/($AV$1^2))+(1/($AV$2^2))) -> 0 | AX17: =((V17/($AV$1^2))+(AJ17/($AV$2^2)))/((1/($AV$1^2))+(1/($AV$2^2))) -> 0.06761947 | AY17: =((W17/($AV$1^2))+(AK17/($AV$2^2)))/((1/($AV$1^2))+(1/($AV$2^2))) -> 0 | ... BC17: =((AA17/($AV$1^2))+(AO17/($AV$2^2)))/((1/($AV$1^2))+(1/($AV$2^2))) -> 16.914248 | BE17: 8 | BF17: =((B17/($BI$1^2))+(P17/($AV$1^2))+(AD17/($AV$2^2)))/((1/($BI$1^2))+(1/($AV$1^2))+(1/($AV$2^2))) -> 0 | BG17: =((C17/($BI$1^2))+(Q17/($AV$1^2))+(AE17/($AV$2^2)))/((1/($BI$1^2))+(1/($AV$1^2))+(1/($AV$2^2))) -> 0 | BH17: =((D17/($BI$1^2))+(R17/($AV$1^2))+(AF17/($AV$2^2)))/((1/($BI$1^2))+(1/($AV$1^2))+(1/($AV$2^2))) -> 0 | BI17: =((E17/($BI$1^2))+(S17/($AV$1^2))+(AG17/($AV$2^2)))/((1/($BI$1^2))+(1/($AV$1^2))+(1/($AV$2^2))) -> 31.958471 | BJ17: =((F17/($BI$1^2))+(T17/($AV$1^2))+(AH17/($AV$2^2)))/((1/($BI$1^2))+(1/($AV$1^2))+(1/($AV$2^2))) -> 41.14194 | BK17: =((G17/($BI$1^2))+(U17/($AV$1^2))+(AI17/($AV$2^2)))/((1/($BI$1^2))+(1/($AV$1^2))+(1/($AV$2^2))) -> 0 | BL17: =((H17/($BI$1^2))+(V17/($AV$1^2))+(AJ17/($AV$2^2)))/((1/($BI$1^2))+(1/($AV$1^2))+(1/($AV$2^2))) -> 0.059151931 | BM17: =((I17/($BI$1^2))+(W17/($AV$1^2))+(AK17/($AV$2^2)))/((1/($BI$1^2))+(1/($AV$1^2))+(1/($AV$2^2))) -> 0 | ... BQ17: =((M17/($BI$1^2))+(AA17/($AV$1^2))+(AO17/($AV$2^2)))/((1/($BI$1^2))+(1/($AV$1^2))+(1/($AV$2^2))) -> 17.306049
A18: 9 | B18: =IF('Data 2'!B18<0.1,0,'Data 2'!B18) -> 0.82137096 | C18: =IF('Data 2'!C18<0.1,0,'Data 2'!C18) -> 14.916097 | D18: =IF('Data 2'!D18<0.1,0,'Data 2'!D18) -> 0 | E18: =IF('Data 2'!E18<0.1,0,'Data 2'!E18) -> 0.13141935 | F18: =IF('Data 2'!F18<0.1,0,'Data 2'!F18) -> 0 | G18: =IF('Data 2'!G18<0.1,0,'Data 2'!G18) -> 0 | H18: =IF('Data 2'!H18<0.1,0,'Data 2'!H18) -> 7.3859678 | I18: =IF('Data 2'!I18<0.1,0,'Data 2'!I18) -> 0 | ... M18: =IF('Data 2'!M18<0.1,0,'Data 2'!M18) -> 10.071774 | O18: 9 | P18: ='Stasiun Pontianak Kota'!Q60 -> 0 | Q18: ='Stasiun Pontianak Kota'!R60 -> 0 | R18: ='Stasiun Pontianak Kota'!S60 -> 0 | S18: ='Stasiun Pontianak Kota'!T60 -> 0 | T18: ='Stasiun Pontianak Kota'!U60 -> 0 | U18: ='Stasiun Pontianak Kota'!V60 -> 0 | V18: ='Stasiun Pontianak Kota'!W60 -> 11 | W18: ='Stasiun Pontianak Kota'!X60 -> 0 | ... AA18: ='Stasiun Pontianak Kota'!AB60 -> 15 | AC18: 9 | AD18: ='Sta. Meteorologi pnk'!B16 -> 2.5 | AE18: ='Sta. Meteorologi pnk'!C16 -> 45.4 | AF18: ='Sta. Meteorologi pnk'!D16 -> 0 | AG18: ='Sta. Meteorologi pnk'!E16 -> 0.4 | AH18: ='Sta. Meteorologi pnk'!F16 -> 0 | AI18: ='Sta. Meteorologi pnk'!G16 -> 0 | AJ18: ='Sta. Meteorologi pnk'!H16 -> 0 | AK18: ='Sta. Meteorologi pnk'!I16 -> 0 | ... AO18: ='Sta. Meteorologi pnk'!M16 -> 0 | AQ18: 9 | AR18: =((P18/($AV$1^2))+(AD18/($AV$2^2)))/((1/($AV$1^2))+(1/($AV$2^2))) -> 1.6904868 | AS18: =((Q18/($AV$1^2))+(AE18/($AV$2^2)))/((1/($AV$1^2))+(1/($AV$2^2))) -> 30.699239 | AT18: =((R18/($AV$1^2))+(AF18/($AV$2^2)))/((1/($AV$1^2))+(1/($AV$2^2))) -> 0 | AU18: =((S18/($AV$1^2))+(AG18/($AV$2^2)))/((1/($AV$1^2))+(1/($AV$2^2))) -> 0.27047788 | AV18: =((T18/($AV$1^2))+(AH18/($AV$2^2)))/((1/($AV$1^2))+(1/($AV$2^2))) -> 0 | AW18: =((U18/($AV$1^2))+(AI18/($AV$2^2)))/((1/($AV$1^2))+(1/($AV$2^2))) -> 0 | AX18: =((V18/($AV$1^2))+(AJ18/($AV$2^2)))/((1/($AV$1^2))+(1/($AV$2^2))) -> 3.5618583 | AY18: =((W18/($AV$1^2))+(AK18/($AV$2^2)))/((1/($AV$1^2))+(1/($AV$2^2))) -> 0 | ... BC18: =((AA18/($AV$1^2))+(AO18/($AV$2^2)))/((1/($AV$1^2))+(1/($AV$2^2))) -> 4.8570795 | BE18: 9 | BF18: =((B18/($BI$1^2))+(P18/($AV$1^2))+(AD18/($AV$2^2)))/((1/($BI$1^2))+(1/($AV$1^2))+(1/($AV$2^2))) -> 1.5816531 | BG18: =((C18/($BI$1^2))+(Q18/($AV$1^2))+(AE18/($AV$2^2)))/((1/($BI$1^2))+(1/($AV$1^2))+(1/($AV$2^2))) -> 28.722821 | BH18: =((D18/($BI$1^2))+(R18/($AV$1^2))+(AF18/($AV$2^2)))/((1/($BI$1^2))+(1/($AV$1^2))+(1/($AV$2^2))) -> 0 | BI18: =((E18/($BI$1^2))+(S18/($AV$1^2))+(AG18/($AV$2^2)))/((1/($BI$1^2))+(1/($AV$1^2))+(1/($AV$2^2))) -> 0.2530645 | BJ18: =((F18/($BI$1^2))+(T18/($AV$1^2))+(AH18/($AV$2^2)))/((1/($BI$1^2))+(1/($AV$1^2))+(1/($AV$2^2))) -> 0 | BK18: =((G18/($BI$1^2))+(U18/($AV$1^2))+(AI18/($AV$2^2)))/((1/($BI$1^2))+(1/($AV$1^2))+(1/($AV$2^2))) -> 0 | BL18: =((H18/($BI$1^2))+(V18/($AV$1^2))+(AJ18/($AV$2^2)))/((1/($BI$1^2))+(1/($AV$1^2))+(1/($AV$2^2))) -> 4.0407262 | BM18: =((I18/($BI$1^2))+(W18/($AV$1^2))+(AK18/($AV$2^2)))/((1/($BI$1^2))+(1/($AV$1^2))+(1/($AV$2^2))) -> 0 | ... BQ18: =((M18/($BI$1^2))+(AA18/($AV$1^2))+(AO18/($AV$2^2)))/((1/($BI$1^2))+(1/($AV$1^2))+(1/($AV$2^2))) -> 5.5100812
A19: 10 | B19: =IF('Data 2'!B19<0.1,0,'Data 2'!B19) -> 1.8070161 | C19: =IF('Data 2'!C19<0.1,0,'Data 2'!C19) -> 36.78629 | D19: =IF('Data 2'!D19<0.1,0,'Data 2'!D19) -> 0 | E19: =IF('Data 2'!E19<0.1,0,'Data 2'!E19) -> 6.2956935 | F19: =IF('Data 2'!F19<0.1,0,'Data 2'!F19) -> 1.7741613 | G19: =IF('Data 2'!G19<0.1,0,'Data 2'!G19) -> 1.7741613 | H19: =IF('Data 2'!H19<0.1,0,'Data 2'!H19) -> 13.509403 | I19: =IF('Data 2'!I19<0.1,0,'Data 2'!I19) -> 1.4456129 | ... M19: =IF('Data 2'!M19<0.1,0,'Data 2'!M19) -> 2.9569355 | O19: 10 | P19: ='Stasiun Pontianak Kota'!Q61 -> 0 | Q19: ='Stasiun Pontianak Kota'!R61 -> 45 | R19: ='Stasiun Pontianak Kota'!S61 -> 0 | S19: ='Stasiun Pontianak Kota'!T61 -> 6 | T19: ='Stasiun Pontianak Kota'!U61 -> 0 | U19: ='Stasiun Pontianak Kota'!V61 -> 0 | V19: ='Stasiun Pontianak Kota'!W61 -> 5 | W19: ='Stasiun Pontianak Kota'!X61 -> 0 | ... AA19: ='Stasiun Pontianak Kota'!AB61 -> 0 | AC19: 10 | AD19: ='Sta. Meteorologi pnk'!B17 -> 5.5 | AE19: ='Sta. Meteorologi pnk'!C17 -> 20 | AF19: ='Sta. Meteorologi pnk'!D17 -> 0 | AG19: ='Sta. Meteorologi pnk'!E17 -> 6.9 | AH19: ='Sta. Meteorologi pnk'!F17 -> 5.4 | AI19: ='Sta. Meteorologi pnk'!G17 -> 5.4 | AJ19: ='Sta. Meteorologi pnk'!H17 -> 30.9 | AK19: ='Sta. Meteorologi pnk'!I17 -> 4.4 | ... AO19: ='Sta. Meteorologi pnk'!M17 -> 9 | AQ19: 10 | AR19: =((P19/($AV$1^2))+(AD19/($AV$2^2)))/((1/($AV$1^2))+(1/($AV$2^2))) -> 3.7190709 | AS19: =((Q19/($AV$1^2))+(AE19/($AV$2^2)))/((1/($AV$1^2))+(1/($AV$2^2))) -> 28.095132 | AT19: =((R19/($AV$1^2))+(AF19/($AV$2^2)))/((1/($AV$1^2))+(1/($AV$2^2))) -> 0 | AU19: =((S19/($AV$1^2))+(AG19/($AV$2^2)))/((1/($AV$1^2))+(1/($AV$2^2))) -> 6.6085752 | AV19: =((T19/($AV$1^2))+(AH19/($AV$2^2)))/((1/($AV$1^2))+(1/($AV$2^2))) -> 3.6514514 | AW19: =((U19/($AV$1^2))+(AI19/($AV$2^2)))/((1/($AV$1^2))+(1/($AV$2^2))) -> 3.6514514 | AX19: =((V19/($AV$1^2))+(AJ19/($AV$2^2)))/((1/($AV$1^2))+(1/($AV$2^2))) -> 22.513443 | AY19: =((W19/($AV$1^2))+(AK19/($AV$2^2)))/((1/($AV$1^2))+(1/($AV$2^2))) -> 2.9752567 | ... BC19: =((AA19/($AV$1^2))+(AO19/($AV$2^2)))/((1/($AV$1^2))+(1/($AV$2^2))) -> 6.0857523 | BE19: 10 | BF19: =((B19/($BI$1^2))+(P19/($AV$1^2))+(AD19/($AV$2^2)))/((1/($BI$1^2))+(1/($AV$1^2))+(1/($AV$2^2))) -> 3.4796369 | BG19: =((C19/($BI$1^2))+(Q19/($AV$1^2))+(AE19/($AV$2^2)))/((1/($BI$1^2))+(1/($AV$1^2))+(1/($AV$2^2))) -> 29.183469 | BH19: =((D19/($BI$1^2))+(R19/($AV$1^2))+(AF19/($AV$2^2)))/((1/($BI$1^2))+(1/($AV$1^2))+(1/($AV$2^2))) -> 0 | BI19: =((E19/($BI$1^2))+(S19/($AV$1^2))+(AG19/($AV$2^2)))/((1/($BI$1^2))+(1/($AV$1^2))+(1/($AV$2^2))) -> 6.5693951 | BJ19: =((F19/($BI$1^2))+(T19/($AV$1^2))+(AH19/($AV$2^2)))/((1/($BI$1^2))+(1/($AV$1^2))+(1/($AV$2^2))) -> 3.4163708 | BK19: =((G19/($BI$1^2))+(U19/($AV$1^2))+(AI19/($AV$2^2)))/((1/($BI$1^2))+(1/($AV$1^2))+(1/($AV$2^2))) -> 3.4163708 | BL19: =((H19/($BI$1^2))+(V19/($AV$1^2))+(AJ19/($AV$2^2)))/((1/($BI$1^2))+(1/($AV$1^2))+(1/($AV$2^2))) -> 21.385926 | BM19: =((I19/($BI$1^2))+(W19/($AV$1^2))+(AK19/($AV$2^2)))/((1/($BI$1^2))+(1/($AV$1^2))+(1/($AV$2^2))) -> 2.7837095 | ... BQ19: =((M19/($BI$1^2))+(AA19/($AV$1^2))+(AO19/($AV$2^2)))/((1/($BI$1^2))+(1/($AV$1^2))+(1/($AV$2^2))) -> 5.6939513
A20: 11 | B20: =IF('Data 2'!B20<0.1,0,'Data 2'!B20) -> 4.7001613 | C20: =IF('Data 2'!C20<0.1,0,'Data 2'!C20) -> 8.6858065 | D20: =IF('Data 2'!D20<0.1,0,'Data 2'!D20) -> 0 | E20: =IF('Data 2'!E20<0.1,0,'Data 2'!E20) -> 16.114839 | F20: =IF('Data 2'!F20<0.1,0,'Data 2'!F20) -> 5.9671452 | G20: =IF('Data 2'!G20<0.1,0,'Data 2'!G20) -> 16.720887 | H20: =IF('Data 2'!H20<0.1,0,'Data 2'!H20) -> 3.3572581 | I20: =IF('Data 2'!I20<0.1,0,'Data 2'!I20) -> 2.6858065 | ... M20: =IF('Data 2'!M20<0.1,0,'Data 2'!M20) -> 9.2424193 | O20: 11 | P20: ='Stasiun Pontianak Kota'!Q62 -> 7 | Q20: ='Stasiun Pontianak Kota'!R62 -> 10 | R20: ='Stasiun Pontianak Kota'!S62 -> 0 | S20: ='Stasiun Pontianak Kota'!T62 -> 24 | T20: ='Stasiun Pontianak Kota'!U62 -> 6 | U20: ='Stasiun Pontianak Kota'!V62 -> 9 | V20: ='Stasiun Pontianak Kota'!W62 -> 5 | W20: ='Stasiun Pontianak Kota'!X62 -> 4 | ... AA20: ='Stasiun Pontianak Kota'!AB62 -> 3 | AC20: 11 | AD20: ='Sta. Meteorologi pnk'!B18 -> 0 | AE20: ='Sta. Meteorologi pnk'!C18 -> 6 | AF20: ='Sta. Meteorologi pnk'!D18 -> 0 | AG20: ='Sta. Meteorologi pnk'!E18 -> 0 | AH20: ='Sta. Meteorologi pnk'!F18 -> 5.9 | AI20: ='Sta. Meteorologi pnk'!G18 -> 32.5 | AJ20: ='Sta. Meteorologi pnk'!H18 -> 0 | AK20: ='Sta. Meteorologi pnk'!I18 -> 0 | ... AO20: ='Sta. Meteorologi pnk'!M18 -> 22 | AQ20: 11 | AR20: =((P20/($AV$1^2))+(AD20/($AV$2^2)))/((1/($AV$1^2))+(1/($AV$2^2))) -> 2.2666371 | AS20: =((Q20/($AV$1^2))+(AE20/($AV$2^2)))/((1/($AV$1^2))+(1/($AV$2^2))) -> 7.2952212 | AT20: =((R20/($AV$1^2))+(AF20/($AV$2^2)))/((1/($AV$1^2))+(1/($AV$2^2))) -> 0 | AU20: =((S20/($AV$1^2))+(AG20/($AV$2^2)))/((1/($AV$1^2))+(1/($AV$2^2))) -> 7.7713272 | AV20: =((T20/($AV$1^2))+(AH20/($AV$2^2)))/((1/($AV$1^2))+(1/($AV$2^2))) -> 5.9323805 | AW20: =((U20/($AV$1^2))+(AI20/($AV$2^2)))/((1/($AV$1^2))+(1/($AV$2^2))) -> 24.890575 | AX20: =((V20/($AV$1^2))+(AJ20/($AV$2^2)))/((1/($AV$1^2))+(1/($AV$2^2))) -> 1.6190265 | AY20: =((W20/($AV$1^2))+(AK20/($AV$2^2)))/((1/($AV$1^2))+(1/($AV$2^2))) -> 1.2952212 | ... BC20: =((AA20/($AV$1^2))+(AO20/($AV$2^2)))/((1/($AV$1^2))+(1/($AV$2^2))) -> 15.847699 | BE20: 11 | BF20: =((B20/($BI$1^2))+(P20/($AV$1^2))+(AD20/($AV$2^2)))/((1/($BI$1^2))+(1/($AV$1^2))+(1/($AV$2^2))) -> 2.5713712 | BG20: =((C20/($BI$1^2))+(Q20/($AV$1^2))+(AE20/($AV$2^2)))/((1/($BI$1^2))+(1/($AV$1^2))+(1/($AV$2^2))) -> 7.469355 | BH20: =((D20/($BI$1^2))+(R20/($AV$1^2))+(AF20/($AV$2^2)))/((1/($BI$1^2))+(1/($AV$1^2))+(1/($AV$2^2))) -> 0 | BI20: =((E20/($BI$1^2))+(S20/($AV$1^2))+(AG20/($AV$2^2)))/((1/($BI$1^2))+(1/($AV$1^2))+(1/($AV$2^2))) -> 8.81613 | BJ20: =((F20/($BI$1^2))+(T20/($AV$1^2))+(AH20/($AV$2^2)))/((1/($BI$1^2))+(1/($AV$1^2))+(1/($AV$2^2))) -> 5.9367339 | BK20: =((G20/($BI$1^2))+(U20/($AV$1^2))+(AI20/($AV$2^2)))/((1/($BI$1^2))+(1/($AV$1^2))+(1/($AV$2^2))) -> 23.867539 | BL20: =((H20/($BI$1^2))+(V20/($AV$1^2))+(AJ20/($AV$2^2)))/((1/($BI$1^2))+(1/($AV$1^2))+(1/($AV$2^2))) -> 1.8366937 | BM20: =((I20/($BI$1^2))+(W20/($AV$1^2))+(AK20/($AV$2^2)))/((1/($BI$1^2))+(1/($AV$1^2))+(1/($AV$2^2))) -> 1.469355 | ... BQ20: =((M20/($BI$1^2))+(AA20/($AV$1^2))+(AO20/($AV$2^2)))/((1/($BI$1^2))+(1/($AV$1^2))+(1/($AV$2^2))) -> 15.020564
A21: 12 | B21: =IF('Data 2'!B21<0.1,0,'Data 2'!B21) -> 0 | C21: =IF('Data 2'!C21<0.1,0,'Data 2'!C21) -> 5.3716129 | D21: =IF('Data 2'!D21<0.1,0,'Data 2'!D21) -> 0 | E21: =IF('Data 2'!E21<0.1,0,'Data 2'!E21) -> 0 | F21: =IF('Data 2'!F21<0.1,0,'Data 2'!F21) -> 12.848161 | G21: =IF('Data 2'!G21<0.1,0,'Data 2'!G21) -> 24.237968 | H21: =IF('Data 2'!H21<0.1,0,'Data 2'!H21) -> 2.6940968 | I21: =IF('Data 2'!I21<0.1,0,'Data 2'!I21) -> 0 | ... M21: =IF('Data 2'!M21<0.1,0,'Data 2'!M21) -> 15.443387 | O21: 12 | P21: ='Stasiun Pontianak Kota'!Q63 -> 0 | Q21: ='Stasiun Pontianak Kota'!R63 -> 8 | R21: ='Stasiun Pontianak Kota'!S63 -> 0 | S21: ='Stasiun Pontianak Kota'!T63 -> 0 | T21: ='Stasiun Pontianak Kota'!U63 -> 7 | U21: ='Stasiun Pontianak Kota'!V63 -> 36 | V21: ='Stasiun Pontianak Kota'!W63 -> 0 | W21: ='Stasiun Pontianak Kota'!X63 -> 0 | ... AA21: ='Stasiun Pontianak Kota'!AB63 -> 23 | AC21: 12 | AD21: ='Sta. Meteorologi pnk'!B19 -> 0 | AE21: ='Sta. Meteorologi pnk'!C19 -> 0 | AF21: ='Sta. Meteorologi pnk'!D19 -> 0 | AG21: ='Sta. Meteorologi pnk'!E19 -> 0 | AH21: ='Sta. Meteorologi pnk'!F19 -> 24.8 | AI21: ='Sta. Meteorologi pnk'!G19 -> 0.2 | AJ21: ='Sta. Meteorologi pnk'!H19 -> 8.2 | AK21: ='Sta. Meteorologi pnk'!I19 -> 0 | ... AO21: ='Sta. Meteorologi pnk'!M19 -> 0 | AQ21: 12 | AR21: =((P21/($AV$1^2))+(AD21/($AV$2^2)))/((1/($AV$1^2))+(1/($AV$2^2))) -> 0 | AS21: =((Q21/($AV$1^2))+(AE21/($AV$2^2)))/((1/($AV$1^2))+(1/($AV$2^2))) -> 2.5904424 | AT21: =((R21/($AV$1^2))+(AF21/($AV$2^2)))/((1/($AV$1^2))+(1/($AV$2^2))) -> 0 | AU21: =((S21/($AV$1^2))+(AG21/($AV$2^2)))/((1/($AV$1^2))+(1/($AV$2^2))) -> 0 | AV21: =((T21/($AV$1^2))+(AH21/($AV$2^2)))/((1/($AV$1^2))+(1/($AV$2^2))) -> 19.036266 | AW21: =((U21/($AV$1^2))+(AI21/($AV$2^2)))/((1/($AV$1^2))+(1/($AV$2^2))) -> 11.79223 | AX21: =((V21/($AV$1^2))+(AJ21/($AV$2^2)))/((1/($AV$1^2))+(1/($AV$2^2))) -> 5.5447965 | AY21: =((W21/($AV$1^2))+(AK21/($AV$2^2)))/((1/($AV$1^2))+(1/($AV$2^2))) -> 0 | ... BC21: =((AA21/($AV$1^2))+(AO21/($AV$2^2)))/((1/($AV$1^2))+(1/($AV$2^2))) -> 7.4475219 | BE21: 12 | BF21: =((B21/($BI$1^2))+(P21/($AV$1^2))+(AD21/($AV$2^2)))/((1/($BI$1^2))+(1/($AV$1^2))+(1/($AV$2^2))) -> 0 | BG21: =((C21/($BI$1^2))+(Q21/($AV$1^2))+(AE21/($AV$2^2)))/((1/($BI$1^2))+(1/($AV$1^2))+(1/($AV$2^2))) -> 2.93871 | BH21: =((D21/($BI$1^2))+(R21/($AV$1^2))+(AF21/($AV$2^2)))/((1/($BI$1^2))+(1/($AV$1^2))+(1/($AV$2^2))) -> 0 | BI21: =((E21/($BI$1^2))+(S21/($AV$1^2))+(AG21/($AV$2^2)))/((1/($BI$1^2))+(1/($AV$1^2))+(1/($AV$2^2))) -> 0 | BJ21: =((F21/($BI$1^2))+(T21/($AV$1^2))+(AH21/($AV$2^2)))/((1/($BI$1^2))+(1/($AV$1^2))+(1/($AV$2^2))) -> 18.26137 | BK21: =((G21/($BI$1^2))+(U21/($AV$1^2))+(AI21/($AV$2^2)))/((1/($BI$1^2))+(1/($AV$1^2))+(1/($AV$2^2))) -> 13.350727 | BL21: =((H21/($BI$1^2))+(V21/($AV$1^2))+(AJ21/($AV$2^2)))/((1/($BI$1^2))+(1/($AV$1^2))+(1/($AV$2^2))) -> 5.1878223 | BM21: =((I21/($BI$1^2))+(W21/($AV$1^2))+(AK21/($AV$2^2)))/((1/($BI$1^2))+(1/($AV$1^2))+(1/($AV$2^2))) -> 0 | ... BQ21: =((M21/($BI$1^2))+(AA21/($AV$1^2))+(AO21/($AV$2^2)))/((1/($BI$1^2))+(1/($AV$1^2))+(1/($AV$2^2))) -> 8.4487912
... A40: 31 | B40: =IF('Data 2'!B40<0.1,0,'Data 2'!B40) -> 0 | C40: =IF('Data 2'!C40<0.1,0,'Data 2'!C40) -> 0 | D40: =IF('Data 2'!D40<0.1,0,'Data 2'!D40) -> 2 | E40: =IF('Data 2'!E40<0.1,0,'Data 2'!E40) -> 0 | F40: =IF('Data 2'!F40<0.1,0,'Data 2'!F40) -> 1.3429032 | G40: =IF('Data 2'!G40<0.1,0,'Data 2'!G40) -> 0 | H40: =IF('Data 2'!H40<0.1,0,'Data 2'!H40) -> 0 | I40: =IF('Data 2'!I40<0.1,0,'Data 2'!I40) -> 37.60129 | ... M40: =IF('Data 2'!M40<0.1,0,'Data 2'!M40) -> 1.1827742 | O40: 31 | P40: ='Stasiun Pontianak Kota'!Q82 -> 0 | Q40: ='Stasiun Pontianak Kota'!R82 -> 0 | R40: ='Stasiun Pontianak Kota'!S82 -> 2 | S40: ='Stasiun Pontianak Kota'!T82 -> 0 | T40: ='Stasiun Pontianak Kota'!U82 -> 2 | U40: ='Stasiun Pontianak Kota'!V82 -> 0 | V40: ='Stasiun Pontianak Kota'!W82 -> 0 | W40: ='Stasiun Pontianak Kota'!X82 -> 56 | ... AA40: ='Stasiun Pontianak Kota'!AB82 -> 0 | AC40: 31 | AD40: ='Sta. Meteorologi pnk'!B38 -> 0 | AE40: ='Sta. Meteorologi pnk'!C38 -> 0 | AF40: ='Sta. Meteorologi pnk'!D38 -> 2 | AG40: ='Sta. Meteorologi pnk'!E38 -> 0 | AH40: ='Sta. Meteorologi pnk'!F38 -> 0 | AI40: ='Sta. Meteorologi pnk'!G38 -> 0 | AJ40: ='Sta. Meteorologi pnk'!H38 -> 0 | AK40: ='Sta. Meteorologi pnk'!I38 -> 0 | ... AO40: ='Sta. Meteorologi pnk'!M38 -> 3.6 | AQ40: 31 | AR40: =((P40/($AV$1^2))+(AD40/($AV$2^2)))/((1/($AV$1^2))+(1/($AV$2^2))) -> 0 | AS40: =((Q40/($AV$1^2))+(AE40/($AV$2^2)))/((1/($AV$1^2))+(1/($AV$2^2))) -> 0 | AT40: =((R40/($AV$1^2))+(AF40/($AV$2^2)))/((1/($AV$1^2))+(1/($AV$2^2))) -> 2 | AU40: =((S40/($AV$1^2))+(AG40/($AV$2^2)))/((1/($AV$1^2))+(1/($AV$2^2))) -> 0 | AV40: =((T40/($AV$1^2))+(AH40/($AV$2^2)))/((1/($AV$1^2))+(1/($AV$2^2))) -> 0.6476106 | AW40: =((U40/($AV$1^2))+(AI40/($AV$2^2)))/((1/($AV$1^2))+(1/($AV$2^2))) -> 0 | AX40: =((V40/($AV$1^2))+(AJ40/($AV$2^2)))/((1/($AV$1^2))+(1/($AV$2^2))) -> 0 | AY40: =((W40/($AV$1^2))+(AK40/($AV$2^2)))/((1/($AV$1^2))+(1/($AV$2^2))) -> 18.133097 | ... BC40: =((AA40/($AV$1^2))+(AO40/($AV$2^2)))/((1/($AV$1^2))+(1/($AV$2^2))) -> 2.4343009 | BE40: 31 | BF40: =((B40/($BI$1^2))+(P40/($AV$1^2))+(AD40/($AV$2^2)))/((1/($BI$1^2))+(1/($AV$1^2))+(1/($AV$2^2))) -> 0 | BG40: =((C40/($BI$1^2))+(Q40/($AV$1^2))+(AE40/($AV$2^2)))/((1/($BI$1^2))+(1/($AV$1^2))+(1/($AV$2^2))) -> 0 | BH40: =((D40/($BI$1^2))+(R40/($AV$1^2))+(AF40/($AV$2^2)))/((1/($BI$1^2))+(1/($AV$1^2))+(1/($AV$2^2))) -> 2 | BI40: =((E40/($BI$1^2))+(S40/($AV$1^2))+(AG40/($AV$2^2)))/((1/($BI$1^2))+(1/($AV$1^2))+(1/($AV$2^2))) -> 0 | BJ40: =((F40/($BI$1^2))+(T40/($AV$1^2))+(AH40/($AV$2^2)))/((1/($BI$1^2))+(1/($AV$1^2))+(1/($AV$2^2))) -> 0.7346775 | BK40: =((G40/($BI$1^2))+(U40/($AV$1^2))+(AI40/($AV$2^2)))/((1/($BI$1^2))+(1/($AV$1^2))+(1/($AV$2^2))) -> 0 | BL40: =((H40/($BI$1^2))+(V40/($AV$1^2))+(AJ40/($AV$2^2)))/((1/($BI$1^2))+(1/($AV$1^2))+(1/($AV$2^2))) -> 0 | BM40: =((I40/($BI$1^2))+(W40/($AV$1^2))+(AK40/($AV$2^2)))/((1/($BI$1^2))+(1/($AV$1^2))+(1/($AV$2^2))) -> 20.57097 | ... BQ40: =((M40/($BI$1^2))+(AA40/($AV$1^2))+(AO40/($AV$2^2)))/((1/($BI$1^2))+(1/($AV$1^2))+(1/($AV$2^2))) -> 2.2775805
A41: Jlh | B41: =SUM(B10:B40) -> 142.31611 | C41: =SUM(C10:C40) -> 298.56713 | D41: =SUM(D10:D40) -> 121.42773 | E41: =SUM(E10:E40) -> 436.1946 | F41: =SUM(F10:F40) -> 358.33208 | G41: =SUM(G10:G40) -> 101.44147 | H41: =SUM(H10:H40) -> 264.15376 | I41: =SUM(I10:I40) -> 144.85008 | ... M41: =SUM(M10:M40) -> 392.48069 | O41: Jlh | P41: =SUM(P10:P40) -> 148 | Q41: =SUM(Q10:Q40) -> 278 | R41: =SUM(R10:R40) -> 89 | S41: =SUM(S10:S40) -> 461 | T41: =SUM(T10:T40) -> 388 | U41: =SUM(U10:U40) -> 102 | V41: =SUM(V10:V40) -> 277 | W41: =SUM(W10:W40) -> 146 | ... AA41: =SUM(AA10:AA40) -> 382 | AC41: Jlh | AD41: =SUM(AD10:AD40) -> 130.7 | AE41: =SUM(AE10:AE40) -> 340.6 | AF41: =SUM(AF10:AF40) -> 187.7 | AG41: =SUM(AG10:AG40) -> 386 | AH41: =SUM(AH10:AH40) -> 297.7 | AI41: =SUM(AI10:AI40) -> 100.6 | AJ41: =SUM(AJ10:AJ40) -> 238 | AK41: =SUM(AK10:AK40) -> 142.5 | ... AO41: =SUM(AO10:AO40) -> 413.9 | AQ41: Jlh | AR41: =SUM(AR10:AR40) -> 136.30183 | AS41: =SUM(AS10:AS40) -> 320.32979 | AT41: =SUM(AT10:AT40) -> 155.74042 | AU41: =SUM(AU10:AU40) -> 410.2854 | AV41: =SUM(AV10:AV40) -> 326.93962 | AW41: =SUM(AW10:AW40) -> 101.05333 | AX41: =SUM(AX10:AX40) -> 250.62841 | AY41: =SUM(AY10:AY40) -> 143.63332 | ... BC41: =SUM(BC10:BC40) -> 403.57061 | BE41: Jlh | BF41: =SUM(BF10:BF40) -> 137.05496 | BG41: =SUM(BG10:BG40) -> 317.60459 | BH41: =SUM(BH10:BH40) -> 151.44367 | BI41: =SUM(BI10:BI40) -> 413.52984 | BJ41: =SUM(BJ10:BJ40) -> 330.87069 | BK41: =SUM(BK10:BK40) -> 101.10193 | BL41: =SUM(BL10:BL40) -> 252.3221 | BM41: =SUM(BM10:BM40) -> 143.78569 | ... BQ41: =SUM(BQ10:BQ40) -> 402.18189
A42: R maks | B42: =MAX(B10:B40) -> 36.929839 | C42: =MAX(C10:C40) -> 51.252323 | D42: =MAX(D10:D40) -> 31.731403 | E42: =MAX(E10:E40) -> 70.229984 | F42: =MAX(F10:F40) -> 75.202581 | G42: =MAX(G10:G40) -> 24.607968 | H42: =MAX(H10:H40) -> 42.046903 | I42: =MAX(I10:I40) -> 37.60129 | ... M42: =MAX(M10:M40) -> 84.266678 | O42: R maks | P42: =MAX(P10:P40) -> 55 | Q42: =MAX(Q10:Q40) -> 64 | R42: =MAX(R10:R40) -> 32 | S42: =MAX(S10:S40) -> 91 | T42: =MAX(T10:T40) -> 112 | U42: =MAX(U10:U40) -> 36 | V42: =MAX(V10:V40) -> 59 | W42: =MAX(W10:W40) -> 56 | ... AA42: =MAX(AA10:AA40) -> 98 | AC42: R maks | AD42: =MAX(AD10:AD40) -> 44.3 | AE42: =MAX(AE10:AE40) -> 110.5 | AF42: =MAX(AF10:AF40) -> 74.1 | AG42: =MAX(AG10:AG40) -> 101 | AH42: =MAX(AH10:AH40) -> 67 | AI42: =MAX(AI10:AI40) -> 42.2 | AJ42: =MAX(AJ10:AJ40) -> 94.4 | AK42: =MAX(AK10:AK40) -> 61 | ... AO42: =MAX(AO10:AO40) -> 98 | AQ42: R maks | AR42: =MAX(AR10:AR40) -> 29.955425 | AS42: =MAX(AS10:AS40) -> 74.719514 | AT42: =MAX(AT10:AT40) -> 53.667886 | AU42: =MAX(AU10:AU40) -> 70.473336 | AV42: =MAX(AV10:AV40) -> 48.299062 | AW42: =MAX(AW10:AW40) -> 33.716301 | AX42: =MAX(AX10:AX40) -> 67.718443 | AY42: =MAX(AY10:AY40) -> 41.247877 | ... BC42: =MAX(BC10:BC40) -> 69.735062 | BE42: R maks | BF42: =MAX(BF10:BF40) -> 28.026893 | BG42: =MAX(BG10:BG40) -> 69.909068 | BH42: =MAX(BH10:BH40) -> 50.920925 | BI42: =MAX(BI10:BI40) -> 70.442863 | BJ42: =MAX(BJ10:BJ40) -> 48.151048 | BK42: =MAX(BK10:BK40) -> 32.575725 | BL42: =MAX(BL10:BL40) -> 64.131287 | BM42: =MAX(BM10:BM40) -> 38.592336 | ... BQ42: =MAX(BQ10:BQ40) -> 71.55476
A43: I | B43: =SUM(B10:B24) -> 42.835419 | C43: =SUM(C10:C24) -> 220.85261 | D43: =SUM(D10:D24) -> 36.979581 | E43: =SUM(E10:E24) -> 214.76173 | F43: =SUM(F10:F24) -> 298.30944 | G43: =SUM(G10:G24) -> 79.624242 | H43: =SUM(H10:H24) -> 204.69218 | I43: =SUM(I10:I24) -> 42.956935 | ... M43: =SUM(M10:M24) -> 175.58532 | O43: I | P43: =SUM(P10:P24) -> 59 | Q43: =SUM(Q10:Q24) -> 197 | R43: =SUM(R10:R24) -> 31 | S43: =SUM(S10:S24) -> 219 | T43: =SUM(T10:T24) -> 331 | U43: =SUM(U10:U24) -> 79 | V43: =SUM(V10:V24) -> 195 | W43: =SUM(W10:W24) -> 40 | ... AA43: =SUM(AA10:AA24) -> 170 | AC43: I | AD43: =SUM(AD10:AD24) -> 9.8 | AE43: =SUM(AE10:AE24) -> 269.6 | AF43: =SUM(AF10:AF24) -> 49.2 | AG43: =SUM(AG10:AG24) -> 206.4 | AH43: =SUM(AH10:AH24) -> 231.5 | AI43: =SUM(AI10:AI24) -> 81.2 | AJ43: =SUM(AJ10:AJ24) -> 224.6 | AK43: =SUM(AK10:AK24) -> 49 | ... AO43: =SUM(AO10:AO24) -> 187 | AQ43: I | AR43: =SUM(AR10:AR24) -> 25.731221 | AS43: =SUM(AS10:AS24) -> 246.09174 | AT43: =SUM(AT10:AT24) -> 43.306744 | AU43: =SUM(AU10:AU24) -> 210.47995 | AV43: =SUM(AV10:AV24) -> 263.71863 | AW43: =SUM(AW10:AW24) -> 80.487628 | AX43: =SUM(AX10:AX24) -> 215.01536 | AY43: =SUM(AY10:AY24) -> 46.085752 | ... BC43: =SUM(BC10:BC24) -> 181.49531 | BE43: I | BF43: =SUM(BF10:BF24) -> 27.873066 | BG43: =SUM(BG10:BG24) -> 242.93121 | BH43: =SUM(BH10:BH24) -> 42.514435 | BI43: =SUM(BI10:BI24) -> 211.01613 | BJ43: =SUM(BJ10:BJ24) -> 268.05021 | BK43: =SUM(BK10:BK24) -> 80.379512 | BL43: =SUM(BL10:BL24) -> 213.72266 | BM43: =SUM(BM10:BM24) -> 45.693951 | ... BQ43: =SUM(BQ10:BQ24) -> 180.75524
A44: II | B44: =SUM(B25:B40) -> 99.480693 | C44: =SUM(C25:C40) -> 77.714516 | D44: =SUM(D25:D40) -> 84.448145 | E44: =SUM(E25:E40) -> 221.43287 | F44: =SUM(F25:F40) -> 60.022645 | G44: =SUM(G25:G40) -> 21.817226 | H44: =SUM(H25:H40) -> 59.461581 | I44: =SUM(I25:I40) -> 101.89315 | ... M44: =SUM(M25:M40) -> 216.89537 | O44: II | P44: =SUM(P25:P40) -> 89 | Q44: =SUM(Q25:Q40) -> 81 | R44: =SUM(R25:R40) -> 58 | S44: =SUM(S25:S40) -> 242 | T44: =SUM(T25:T40) -> 57 | U44: =SUM(U25:U40) -> 23 | V44: =SUM(V25:V40) -> 82 | W44: =SUM(W25:W40) -> 106 | ... AA44: =SUM(AA25:AA40) -> 212 | AC44: II | AD44: =SUM(AD25:AD40) -> 120.9 | AE44: =SUM(AE25:AE40) -> 71 | AF44: =SUM(AF25:AF40) -> 138.5 | AG44: =SUM(AG25:AG40) -> 179.6 | AH44: =SUM(AH25:AH40) -> 66.2 | AI44: =SUM(AI25:AI40) -> 19.4 | AJ44: =SUM(AJ25:AJ40) -> 13.4 | AK44: =SUM(AK25:AK40) -> 93.5 | ... AO44: =SUM(AO25:AO40) -> 226.9 | AQ44: II | AR44: =SUM(AR25:AR40) -> 110.57061 | AS44: =SUM(AS25:AS40) -> 74.238053 | AT44: =SUM(AT25:AT40) -> 112.43367 | AU44: =SUM(AU25:AU40) -> 199.80545 | AV44: =SUM(AV25:AV40) -> 63.220991 | AW44: =SUM(AW25:AW40) -> 20.565699 | AX44: =SUM(AX25:AX40) -> 35.613044 | AY44: =SUM(AY25:AY40) -> 97.547566 | ... BC44: =SUM(BC25:BC40) -> 222.0753 | BE44: II | BF44: =SUM(BF25:BF40) -> 109.18189 | BG44: =SUM(BG25:BG40) -> 74.673387 | BH44: =SUM(BH25:BH40) -> 108.92923 | BI44: =SUM(BI25:BI40) -> 202.51371 | BJ44: =SUM(BJ25:BJ40) -> 62.820484 | BK44: =SUM(BK25:BK40) -> 20.722419 | BL44: =SUM(BL25:BL40) -> 38.599438 | BM44: =SUM(BM25:BM40) -> 98.091734 | ... BQ44: =SUM(BQ25:BQ40) -> 221.42665
A45: HH | B45: =COUNTIF(B12:B42,">0") -> 14 | C45: =COUNTIF(C12:C42,">0") -> 24 | D45: =COUNTIF(D12:D42,">0") -> 18 | E45: =COUNTIF(E12:E42,">0") -> 23 | F45: =COUNTIF(F12:F42,">0") -> 29 | G45: =COUNTIF(G12:G42,">0") -> 12 | H45: =COUNTIF(H12:H42,">0") -> 19 | I45: =COUNTIF(I12:I42,">0") -> 16 | ... M45: =COUNTIF(M12:M42,">0") -> 29 | O45: HH | P45: =COUNTIF(P10:P40,">0") -> 9 | Q45: =COUNTIF(Q10:Q40,">0") -> 13 | R45: =COUNTIF(R10:R40,">0") -> 8 | S45: =COUNTIF(S10:S40,">0") -> 15 | T45: =COUNTIF(T10:T40,">0") -> 22 | U45: =COUNTIF(U10:U40,">0") -> 6 | V45: =COUNTIF(V10:V40,">0") -> 15 | W45: =COUNTIF(W10:W40,">0") -> 9 | ... AA45: =COUNTIF(AA10:AA40,">0") -> 19 | AC45: HH | AD45: =COUNTIF(AD10:AD40,">0") -> 10 | AE45: =COUNTIF(AE10:AE40,">0") -> 17 | AF45: =COUNTIF(AF10:AF40,">0") -> 13 | AG45: =COUNTIF(AG10:AG40,">0") -> 17 | AH45: =COUNTIF(AH10:AH40,">0") -> 25 | AI45: =COUNTIF(AI10:AI40,">0") -> 9 | AJ45: =COUNTIF(AJ10:AJ40,">0") -> 12 | AK45: =COUNTIF(AK10:AK40,">0") -> 8 | ... AO45: =COUNTIF(AO10:AO40,">0") -> 24 | AQ45: HH | AR45: =COUNTIF(AR10:AR40,">0") -> 14 | AS45: =COUNTIF(AS10:AS40,">0") -> 24 | AT45: =COUNTIF(AT10:AT40,">0") -> 16 | AU45: =COUNTIF(AU10:AU40,">0") -> 24 | AV45: =COUNTIF(AV10:AV40,">0") -> 29 | AW45: =COUNTIF(AW10:AW40,">0") -> 11 | AX45: =COUNTIF(AX10:AX40,">0") -> 20 | AY45: =COUNTIF(AY10:AY40,">0") -> 15 | ... BC45: =COUNTIF(BC10:BC40,">0") -> 29 | BE45: HH | BF45: =COUNTIF(BF10:BF40,">0") -> 14 | BG45: =COUNTIF(BG10:BG40,">0") -> 24 | BH45: =COUNTIF(BH10:BH40,">0") -> 16 | BI45: =COUNTIF(BI10:BI40,">0") -> 24 | BJ45: =COUNTIF(BJ10:BJ40,">0") -> 29 | BK45: =COUNTIF(BK10:BK40,">0") -> 11 | BL45: =COUNTIF(BL10:BL40,">0") -> 20 | BM45: =COUNTIF(BM10:BM40,">0") -> 15 | ... BQ45: =COUNTIF(BQ10:BQ40,">0") -> 29
A47: Tahun 2014 | O47: Tahun 2014 | AC47: Tahun 2014 | AQ47: Tahun 2014 | BE47: Tahun 2014
B48: Bulan | P48: Bulan | AD48: Bulan | AR48: Bulan | BF48: Bulan
B49: Jan | C49: Feb | D49: Mar | E49: Apr | F49: Mei | G49: Jun | H49: Jul | I49: Agt | J49: Sept | K49: Okt | L49: Nov | M49: Des | P49: Jan | Q49: Feb | R49: Mar | S49: Apr | T49: Mei | U49: Jun | V49: Jul | W49: Agt | X49: Sept | Y49: Okt | Z49: Nov | AA49: Des | AD49: Jan | AE49: Feb | AF49: Mar | AG49: Apr | AH49: Mei | AI49: Jun | AJ49: Jul | AK49: Agt | AL49: Sept | AM49: Okt | AN49: Nov | AO49: Des | AR49: Jan | AS49: Feb | AT49: Mar | AU49: Apr | AV49: Mei | AW49: Jun | AX49: Jul | AY49: Agt | AZ49: Sept | BA49: Okt | BB49: Nov | BC49: Des | BF49: Jan | BG49: Feb | BH49: Mar | BI49: Apr | BJ49: Mei | BK49: Jun | BL49: Jul | BM49: Agt | BN49: Sept | BO49: Okt | BP49: Nov | BQ49: Des
A50: 1 | B50: =IF('Data 2'!B50<0.1,0,'Data 2'!B50) -> 10.11929 | C50: =IF('Data 2'!C50<0.1,0,'Data 2'!C50) -> 0 | D50: =IF('Data 2'!D50<0.1,0,'Data 2'!D50) -> 11.414677 | E50: =IF('Data 2'!E50<0.1,0,'Data 2'!E50) -> 38.944194 | F50: =IF('Data 2'!F50<0.1,0,'Data 2'!F50) -> 0 | G50: =IF('Data 2'!G50<0.1,0,'Data 2'!G50) -> 8.9693709 | H50: =IF('Data 2'!H50<0.1,0,'Data 2'!H50) -> 0 | I50: =IF('Data 2'!I50<0.1,0,'Data 2'!I50) -> 2.0143548 | ... M50: =IF('Data 2'!M50<0.1,0,'Data 2'!M50) -> 25.867468 | O50: 1 | P50: ='Stasiun Pontianak Kota'!Q96 -> 0 | Q50: ='Stasiun Pontianak Kota'!R96 -> 0 | R50: ='Stasiun Pontianak Kota'!S96 -> 17 | S50: ='Stasiun Pontianak Kota'!T96 -> 58 | T50: ='Stasiun Pontianak Kota'!U96 -> 0 | U50: ='Stasiun Pontianak Kota'!V96 -> 0 | V50: ='Stasiun Pontianak Kota'!W96 -> 0 | W50: ='Stasiun Pontianak Kota'!X96 -> 3 | ... AA50: ='Stasiun Pontianak Kota'!AB96 -> 30.5 | AC50: 1 | AD50: ='Sta. Meteorologi pnk'!B53 -> 30.8 | AE50: ='Sta. Meteorologi pnk'!C53 -> 0 | AF50: ='Sta. Meteorologi pnk'!D53 -> 0 | AG50: ='Sta. Meteorologi pnk'!E53 -> 0 | AH50: ='Sta. Meteorologi pnk'!F53 -> 0 | AI50: ='Sta. Meteorologi pnk'!G53 -> 27.3 | AJ50: ='Sta. Meteorologi pnk'!H53 -> 0 | AK50: ='Sta. Meteorologi pnk'!I53 -> 0 | ... AO50: ='Sta. Meteorologi pnk'!M53 -> 16.4 | AQ50: 1 | AR50: =((P50/($AV$1^2))+(AD50/($AV$2^2)))/((1/($AV$1^2))+(1/($AV$2^2))) -> 20.826797 | AS50: =((Q50/($AV$1^2))+(AE50/($AV$2^2)))/((1/($AV$1^2))+(1/($AV$2^2))) -> 0 | AT50: =((R50/($AV$1^2))+(AF50/($AV$2^2)))/((1/($AV$1^2))+(1/($AV$2^2))) -> 5.5046901 | AU50: =((S50/($AV$1^2))+(AG50/($AV$2^2)))/((1/($AV$1^2))+(1/($AV$2^2))) -> 18.780707 | AV50: =((T50/($AV$1^2))+(AH50/($AV$2^2)))/((1/($AV$1^2))+(1/($AV$2^2))) -> 0 | AW50: =((U50/($AV$1^2))+(AI50/($AV$2^2)))/((1/($AV$1^2))+(1/($AV$2^2))) -> 18.460115 | AX50: =((V50/($AV$1^2))+(AJ50/($AV$2^2)))/((1/($AV$1^2))+(1/($AV$2^2))) -> 0 | AY50: =((W50/($AV$1^2))+(AK50/($AV$2^2)))/((1/($AV$1^2))+(1/($AV$2^2))) -> 0.9714159 | ... BC50: =((AA50/($AV$1^2))+(AO50/($AV$2^2)))/((1/($AV$1^2))+(1/($AV$2^2))) -> 20.965655 | BE50: 1 | BF50: =((B50/($BI$1^2))+(P50/($AV$1^2))+(AD50/($AV$2^2)))/((1/($BI$1^2))+(1/($AV$1^2))+(1/($AV$2^2))) -> 19.485967 | BG50: =((C50/($BI$1^2))+(Q50/($AV$1^2))+(AE50/($AV$2^2)))/((1/($BI$1^2))+(1/($AV$1^2))+(1/($AV$2^2))) -> 0 | BH50: =((D50/($BI$1^2))+(R50/($AV$1^2))+(AF50/($AV$2^2)))/((1/($BI$1^2))+(1/($AV$1^2))+(1/($AV$2^2))) -> 6.2447587 | BI50: =((E50/($BI$1^2))+(S50/($AV$1^2))+(AG50/($AV$2^2)))/((1/($BI$1^2))+(1/($AV$1^2))+(1/($AV$2^2))) -> 21.305647 | BJ50: =((F50/($BI$1^2))+(T50/($AV$1^2))+(AH50/($AV$2^2)))/((1/($BI$1^2))+(1/($AV$1^2))+(1/($AV$2^2))) -> 0 | BK50: =((G50/($BI$1^2))+(U50/($AV$1^2))+(AI50/($AV$2^2)))/((1/($BI$1^2))+(1/($AV$1^2))+(1/($AV$2^2))) -> 17.271652 | BL50: =((H50/($BI$1^2))+(V50/($AV$1^2))+(AJ50/($AV$2^2)))/((1/($BI$1^2))+(1/($AV$1^2))+(1/($AV$2^2))) -> 0 | BM50: =((I50/($BI$1^2))+(W50/($AV$1^2))+(AK50/($AV$2^2)))/((1/($BI$1^2))+(1/($AV$1^2))+(1/($AV$2^2))) -> 1.1020162 | ... BQ50: =((M50/($BI$1^2))+(AA50/($AV$1^2))+(AO50/($AV$2^2)))/((1/($BI$1^2))+(1/($AV$1^2))+(1/($AV$2^2))) -> 21.579476
A51: 2 | B51: =IF('Data 2'!B51<0.1,0,'Data 2'!B51) -> 27.529516 | C51: =IF('Data 2'!C51<0.1,0,'Data 2'!C51) -> 0 | D51: =IF('Data 2'!D51<0.1,0,'Data 2'!D51) -> 0 | E51: =IF('Data 2'!E51<0.1,0,'Data 2'!E51) -> 2.9569355 | F51: =IF('Data 2'!F51<0.1,0,'Data 2'!F51) -> 2.1684193 | G51: =IF('Data 2'!G51<0.1,0,'Data 2'!G51) -> 32.026484 | H51: =IF('Data 2'!H51<0.1,0,'Data 2'!H51) -> 2.0143548 | I51: =IF('Data 2'!I51<0.1,0,'Data 2'!I51) -> 0 | ... M51: =IF('Data 2'!M51<0.1,0,'Data 2'!M51) -> 12.891871 | O51: 2 | P51: ='Stasiun Pontianak Kota'!Q97 -> 41 | Q51: ='Stasiun Pontianak Kota'!R97 -> 0 | R51: ='Stasiun Pontianak Kota'!S97 -> 0 | S51: ='Stasiun Pontianak Kota'!T97 -> 0 | T51: ='Stasiun Pontianak Kota'!U97 -> 0 | U51: ='Stasiun Pontianak Kota'!V97 -> 43 | V51: ='Stasiun Pontianak Kota'!W97 -> 3 | W51: ='Stasiun Pontianak Kota'!X97 -> 0 | ... AA51: ='Stasiun Pontianak Kota'!AB97 -> 19.2 | AC51: 2 | AD51: ='Sta. Meteorologi pnk'!B54 -> 0 | AE51: ='Sta. Meteorologi pnk'!C54 -> 0 | AF51: ='Sta. Meteorologi pnk'!D54 -> 0 | AG51: ='Sta. Meteorologi pnk'!E54 -> 9 | AH51: ='Sta. Meteorologi pnk'!F54 -> 6.6 | AI51: ='Sta. Meteorologi pnk'!G54 -> 9.6 | AJ51: ='Sta. Meteorologi pnk'!H54 -> 0 | AK51: ='Sta. Meteorologi pnk'!I54 -> 0 | ... AO51: ='Sta. Meteorologi pnk'!M54 -> 0 | AQ51: 2 | AR51: =((P51/($AV$1^2))+(AD51/($AV$2^2)))/((1/($AV$1^2))+(1/($AV$2^2))) -> 13.276017 | AS51: =((Q51/($AV$1^2))+(AE51/($AV$2^2)))/((1/($AV$1^2))+(1/($AV$2^2))) -> 0 | AT51: =((R51/($AV$1^2))+(AF51/($AV$2^2)))/((1/($AV$1^2))+(1/($AV$2^2))) -> 0 | AU51: =((S51/($AV$1^2))+(AG51/($AV$2^2)))/((1/($AV$1^2))+(1/($AV$2^2))) -> 6.0857523 | AV51: =((T51/($AV$1^2))+(AH51/($AV$2^2)))/((1/($AV$1^2))+(1/($AV$2^2))) -> 4.462885 | AW51: =((U51/($AV$1^2))+(AI51/($AV$2^2)))/((1/($AV$1^2))+(1/($AV$2^2))) -> 20.415097 | AX51: =((V51/($AV$1^2))+(AJ51/($AV$2^2)))/((1/($AV$1^2))+(1/($AV$2^2))) -> 0.9714159 | AY51: =((W51/($AV$1^2))+(AK51/($AV$2^2)))/((1/($AV$1^2))+(1/($AV$2^2))) -> 0 | ... BC51: =((AA51/($AV$1^2))+(AO51/($AV$2^2)))/((1/($AV$1^2))+(1/($AV$2^2))) -> 6.2170617 | BE51: 2 | BF51: =((B51/($BI$1^2))+(P51/($AV$1^2))+(AD51/($AV$2^2)))/((1/($BI$1^2))+(1/($AV$1^2))+(1/($AV$2^2))) -> 15.060889 | BG51: =((C51/($BI$1^2))+(Q51/($AV$1^2))+(AE51/($AV$2^2)))/((1/($BI$1^2))+(1/($AV$1^2))+(1/($AV$2^2))) -> 0 | BH51: =((D51/($BI$1^2))+(R51/($AV$1^2))+(AF51/($AV$2^2)))/((1/($BI$1^2))+(1/($AV$1^2))+(1/($AV$2^2))) -> 0 | BI51: =((E51/($BI$1^2))+(S51/($AV$1^2))+(AG51/($AV$2^2)))/((1/($BI$1^2))+(1/($AV$1^2))+(1/($AV$2^2))) -> 5.6939513 | BJ51: =((F51/($BI$1^2))+(T51/($AV$1^2))+(AH51/($AV$2^2)))/((1/($BI$1^2))+(1/($AV$1^2))+(1/($AV$2^2))) -> 4.1755643 | BK51: =((G51/($BI$1^2))+(U51/($AV$1^2))+(AI51/($AV$2^2)))/((1/($BI$1^2))+(1/($AV$1^2))+(1/($AV$2^2))) -> 21.869114 | BL51: =((H51/($BI$1^2))+(V51/($AV$1^2))+(AJ51/($AV$2^2)))/((1/($BI$1^2))+(1/($AV$1^2))+(1/($AV$2^2))) -> 1.1020162 | BM51: =((I51/($BI$1^2))+(W51/($AV$1^2))+(AK51/($AV$2^2)))/((1/($BI$1^2))+(1/($AV$1^2))+(1/($AV$2^2))) -> 0 | ... BQ51: =((M51/($BI$1^2))+(AA51/($AV$1^2))+(AO51/($AV$2^2)))/((1/($BI$1^2))+(1/($AV$1^2))+(1/($AV$2^2))) -> 7.052904
